Workbook

Sheet DNI
A1: DELGADO SECLEN ALVARO ELISEO | B1: 80640163
A2: ALVAREZ ALVINES JUAN MANUEL | B2: 46108491
A3: AMAYA CAPUÑAY JOSE ENRIQUE | B3: 45686225
A4: AQUINO SILVA DANTE JESUS ALEXIS | B4: 74863779
A5: AQUINO TEJEDA JUAN JOSE | B5: 80483542
A6: AYALA RAMIREZ RUBEN ISAI | B6: 75557820
A7: BALLENA ADANAQUE MIGUEL ANGEL | B7: 48446313
A8: LABAN SEVERINO EDWIN DENIS | B8: 47466045
A9: MEDINA GUEVARA TIRSO | B9: 16792081
A10: BONILLA RADAELLI CARLOS EDUARDO | B10: 73130745
A11: BUSTAMANTE GONZALES CARLOS | B11: 27291529
A12: CAMIZAN CUNIAS LENDER NEYDEN | B12: 47711616
... A94: CASTILLO LOYOLA ANTONIO | B94: 42435768
A95: SALAZAR AQUINO IRVIN
A96: PLATA ESCALANTE SERGIO | B96: 3548110
A97: SANCHEZ MEOÑO FRANK | B97: 72684512
A98: SOLANO SUELDO CARLOS | B98: 44676684
A99: VIDAURRE YOVERA JOSE | B99: 43705902

Sheet RUBRO
A1: N° | B1: COD. | C1: ESTACION DE TRABAJO | D1: PUESTO DE TRABAJO: PRODUCCION | F1: DNI | G1: CODIGO | H1: PERFIL | I1: ESTACION DE TRABAJO | J1: DETALLE DE PERFIL | K1: OPERARIO | L1: RENTA | M1: DIARIO | N1: EMPRESA | O1: ITEM | Q1: N° | R1: LUGAR | S1: HORAS | T1: ALMUERZO | W1: FECHA | X1: DOMINICAL | Y1: DIA | Z1: DETALLE | AA1: CÓDIGO
A2: 1 | B2: MAE-06 | C2: CORTE Y PLEGADO | D2: MAESTRO DE CORTE Y PLEGADO | F2: =VLOOKUP(K2,DNI!$A$1:$B$10000,2,FALSE) -> 80640163 | G2: =H2&-O2 -> MAE-02-1 | H2: MAE-02 | I2: MONTAJE MN | J2: MAESTRO MECANICO MONTAJISTA DE MAQUINARIA | K2: DELGADO SECLEN ALVARO ELISEO | L2: 5ta | M2: 83.333333 | N2: DELCOR | O2: 001 | Q2: 1 | R2: PLANTA | S2: 0.375 | T2: 0.54166667 | U2: 0.58333333 | W2: 43831 | Y2: =TEXT(W2,"ddddd") -> miércoles | Z2: año nuevo | AA2: 1 | AC2: 0.041666667 | AD2: 0.54166667
A3: 2 | B3: OPE-06 | C3: CORTE Y PLEGADO | D3: OPERARIO DE CORTE Y PLEGADO | F3: =VLOOKUP(K3,DNI!$A$1:$B$10000,2,FALSE) -> 46108491 | G3: =H3&-O3 -> TEC-02-2 | H3: TEC-02 | I3: MONTAJE MN | J3: TECNICO MECANICO MONTAJISTA DE MAQUINARIA | K3: ALVAREZ ALVINES JUAN MANUEL | L3: 5ta | M3: 50 | N3: MECANOS | O3: 002 | Q3: 2 | R3: OBRA | S3: 0.33333333 | T3: 0.54166667 | U3: 0.58333333 | W3: 43832 | Y3: =TEXT(W3,"ddddd") -> jueves | AC3: 0.083333333
A4: 3 | B4: MAEME-03 | C4: ELECTRICIDAD | D4: MAESTRO ELECTRICO MONTAJISTA DE MAQUINARIA EXTRANJERA | F4: =VLOOKUP(K4,DNI!$A$1:$B$10000,2,FALSE) -> 45686225 | G4: =H4&-O4 -> TEC-02-3 | H4: TEC-02 | I4: MONTAJE MN | J4: TECNICO MECANICO MONTAJISTA DE MAQUINARIA | K4: AMAYA CAPUÑAY JOSE ENRIQUE | L4: 4ta | M4: 60 | N4: MECANOS | O4: 003 | Q4: 3 | R4: DESCANSO | W4: 43833 | Y4: =TEXT(W4,"ddddd") -> viernes | AC4: 0.125
A5: 4 | B5: OPE-03 | C5: ELECTRICIDAD | D5: OPERARIO ELECTRICO | F5: =VLOOKUP(K5,DNI!$A$1:$B$10000,2,FALSE) -> 74863779 | G5: =H5&-O5 -> AYU-VA-4 | H5: AYU-VA | I5: VARIAS | J5: AYUDANTE DE PRODUCCION | K5: AQUINO SILVA DANTE JESUS ALEXIS | L5: 4ta | M5: 40 | N5: MECANOS | O5: 004 | Q5: 4 | R5: FALTA | W5: 43834 | Y5: =TEXT(W5,"ddddd") -> sábado | AC5: 0.16666667
A6: 5 | B6: TECME-03 | C6: ELECTRICIDAD | D6: TECNICO ELECTRICO MONTAJISTA DE MAQUINARIA EXTRANJERA | F6: =VLOOKUP(K6,DNI!$A$1:$B$10000,2,FALSE) -> 80483542 | G6: =H6&-O6 -> AYU-VA-5 | H6: AYU-VA | I6: VARIAS | J6: AYUDANTE DE PRODUCCION | K6: AQUINO TEJEDA JUAN JOSE | L6: 4ta | M6: 45 | N6: MECANOS | O6: 005 | Q6: 5 | R6: | | W6: 43835 | X6: 1 | Y6: =TEXT(W6,"ddddd") -> domingo | AC6: 0.20833333
A7: 6 | B7: TECMN-03 | C7: ELECTRICIDAD | D7: TECNICO ELECTRICO MONTAJISTA DE MAQUINARIA | F7: =VLOOKUP(K7,DNI!$A$1:$B$10000,2,FALSE) -> 75557820 | G7: =H7&-O7 -> OPE-03-6 | H7: OPE-03 | I7: ELECTRICIDAD | J7: OPERARIO ELECTRICO | K7: AYALA RAMIREZ RUBEN ISAI | L7: 4ta | M7: 50 | N7: MECANOS | O7: 006 | Q7: 6 | R7: LICENCIA SIN GOCE | W7: 43836 | Y7: =TEXT(W7,"ddddd") -> lunes | AC7: 0.25
A8: 7 | B8: MAE-07 | C8: FACTORIA | D8: MAESTRO MECANICO DE FACTORIA | F8: =VLOOKUP(K8,DNI!$A$1:$B$10000,2,FALSE) -> 48446313 | G8: =H8&-O8 -> TEC-02-7 | H8: TEC-02 | I8: MONTAJE MN | J8: TECNICO MECANICO MONTAJISTA DE MAQUINARIA | K8: BALLENA ADANAQUE MIGUEL ANGEL | L8: 4ta | M8: 50 | N8: MECANOS | O8: 007 | Q8: 7 | R8: DESCANSO MEDICO | W8: 43837 | Y8: =TEXT(W8,"ddddd") -> martes | AC8: 0.29166667
A9: 8 | B9: TEC-07 | C9: FACTORIA | D9: TECNICO MECANICO DE FACTORIA | F9: =VLOOKUP(K9,DNI!$A$1:$B$10000,2,FALSE) -> 10664396 | G9: =H9&-O9 -> OPE-01-8 | H9: OPE-01 | I9: SOLDADURA | J9: OPERARIO SOLDADOR | K9: BENDEZU PISCO JORGE GUILLERMO | L9: 5ta | M9: 60 | N9: MECANOS | O9: 008 | Q9: 8 | R9: H.EXTRAS 5TA | S9: 0.33333333 | T9: 0.54166667 | U9: 0.58333333 | W9: 43838 | Y9: =TEXT(W9,"ddddd") -> miércoles | AC9: 0.33333333
A10: 9 | B10: MAE-04 | C10: MONTAJE ME | D10: MAESTRO MECANICO MONTAJISTA DE MAQUINARIA EXTRANJERA | F10: =VLOOKUP(K10,DNI!$A$1:$B$10000,2,FALSE) -> 71995358 | G10: =H10&-O10 -> OPE-01-9 | H10: OPE-01 | I10: SOLDADURA | J10: OPERARIO SOLDADOR | K10: BONILLA CHAVEZ LUIS DANIEL | L10: 4ta | M10: 45 | N10: MECANOS | O10: 009 | W10: 43839 | Y10: =TEXT(W10,"ddddd") -> jueves | AC10: 0.375
A11: 10 | B11: MEC-04 | C11: MONTAJE ME | D11: MECANICO MONTAJISTA DE MAQUINARIA EXTRANJERA | F11: =VLOOKUP(K11,DNI!$A$1:$B$10000,2,FALSE) -> 73130745 | G11: =H11&-O11 -> AYU-VA-10 | H11: AYU-VA | I11: VARIAS | J11: AYUDANTE DE PRODUCCION | K11: BONILLA RADAELLI CARLOS EDUARDO | L11: 4ta | M11: 40 | N11: MECANOS | O11: 010 | W11: 43840 | Y11: =TEXT(W11,"ddddd") -> viernes | AC11: 0.41666667
A12: 11 | B12: TEC-04 | C12: MONTAJE ME | D12: TECNICO MECANICO MONTAJISTA DE MAQUINARIA EXTRANJERA | F12: =VLOOKUP(K12,DNI!$A$1:$B$10000,2,FALSE) -> 27291529 | G12: =H12&-O12 -> MEC-04-11 | H12: MEC-04 | I12: MONTAJE ME | J12: MECANICO MONTAJISTA DE MAQUINARIA EXTRANJERA | K12: BUSTAMANTE GONZALES CARLOS | L12: 5ta | M12: 72.54 | N12: MECANOS | O12: 011 | W12: 43841 | Y12: =TEXT(W12,"ddddd") -> sábado | AC12: 0.45833333
A13: 12 | B13: MAE-02 | C13: MONTAJE MN | D13: MAESTRO MECANICO MONTAJISTA DE MAQUINARIA | F13: =VLOOKUP(K13,DNI!$A$1:$B$10000,2,FALSE) -> 47711616 | G13: =H13&-O13 -> TECMN-03-12 | H13: TECMN-03 | I13: ELECTRICIDAD | J13: TECNICO ELECTRICO MONTAJISTA DE MAQUINARIA | K13: CAMIZAN CUNIAS LENDER NEYDEN | L13: 5ta | M13: 47.73 | N13: MECANOS | O13: 012 | W13: 43842 | X13: 1 | Y13: =TEXT(W13,"ddddd") -> domingo | AC13: 0.5
A14: 13 | B14: MEC-02 | C14: MONTAJE MN | D14: MECANICO MONTAJISTA DE MAQUINARIA | F14: =VLOOKUP(K14,DNI!$A$1:$B$10000,2,FALSE) -> 48237026 | G14: =H14&-O14 -> TEC-05-13 | H14: TEC-05 | I14: MONTAJE NAVE | J14: TECNICO MECANICO MONTAJISTA DE NAVE INDUSTRIAL | K14: CAVERO ANCAJIMA JHONATAN | L14: 5ta | M14: 52.2 | N14: MECANOS | O14: 013 | W14: 43843 | Y14: =TEXT(W14,"ddddd") -> lunes | AC14: 0.54166667
A15: 14 | B15: TEC-02 | C15: MONTAJE MN | D15: TECNICO MECANICO MONTAJISTA DE MAQUINARIA | F15: =VLOOKUP(K15,DNI!$A$1:$B$10000,2,FALSE) -> 47055982 | G15: =H15&-O15 -> TECME-03-14 | H15: TECME-03 | I15: ELECTRICIDAD | J15: TECNICO ELECTRICO MONTAJISTA DE MAQUINARIA EXTRANJERA | K15: CHAQUILA JIMENEZ VICTOR JHEYNER | L15: 5ta | M15: 73.72 | N15: MECANOS | O15: 014 | W15: 43844 | Y15: =TEXT(W15,"ddddd") -> martes | AC15: 0.58333333
A16: 15 | B16: AYU-05 | C16: MONTAJE NAVE | D16: AYUDANTE MONTAJISTA DE NAVE INDUSTRIAL | F16: =VLOOKUP(K16,DNI!$A$1:$B$10000,2,FALSE) -> 44983080 | G16: =H16&-O16 -> OPE-01-15 | H16: OPE-01 | I16: SOLDADURA | J16: OPERARIO SOLDADOR | K16: CHAVESTA LLUEN WALTER OMAR | L16: 4ta | M16: 75 | N16: TALLERES | O16: 015 | W16: 43845 | Y16: =TEXT(W16,"ddddd") -> miércoles | AC16: 0.625
A17: 16 | B17: MAE-05 | C17: MONTAJE NAVE | D17: MAESTRO MECANICO MONTAJISTA DE NAVE INDUSTRIAL | F17: =VLOOKUP(K17,DNI!$A$1:$B$10000,2,FALSE) -> 75322465 | G17: =H17&-O17 -> AYU-VA-16 | H17: AYU-VA | I17: VARIAS | J17: AYUDANTE DE PRODUCCION | K17: CHERO AYALA JOSE ISMAEL | L17: 4ta | M17: 60 | N17: MECANOS | O17: 016 | W17: 43846 | Y17: =TEXT(W17,"ddddd") -> jueves | AC17: 0.66666667
A18: 17 | B18: TEC-05 | C18: MONTAJE NAVE | D18: TECNICO MECANICO MONTAJISTA DE NAVE INDUSTRIAL | F18: =VLOOKUP(K18,DNI!$A$1:$B$10000,2,FALSE) -> 74359947 | G18: =H18&-O18 -> OPE-01-17 | H18: OPE-01 | I18: SOLDADURA | J18: OPERARIO SOLDADOR | K18: CORDOVA OJEDA JHON GIAMPIERRE | L18: 5ta | M18: 57.62 | N18: MECANOS | O18: 017 | W18: 43847 | Y18: =TEXT(W18,"ddddd") -> viernes | AC18: 0.70833333
A19: 18 | B19: MAE-08 | C19: PINTURA | D19: MAESTRO PINTOR | F19: =VLOOKUP(K19,DNI!$A$1:$B$10000,2,FALSE) -> 75461003 | G19: =H19&-O19 -> OPE-03-18 | H19: OPE-03 | I19: ELECTRICIDAD | J19: OPERARIO ELECTRICO | K19: CORONADO MONJE JEAN CARLOS | L19: 4ta | M19: 40 | N19: MECANOS | O19: 018 | W19: 43848 | Y19: =TEXT(W19,"ddddd") -> sábado | AC19: 0.75
A20: 19 | B20: MAE3G-01 | C20: SOLDADURA | D20: MAESTRO SOLDADOR 3G | F20: =VLOOKUP(K20,DNI!$A$1:$B$10000,2,FALSE) -> 47321409 | G20: =H20&-O20 -> TEC-02-19 | H20: TEC-02 | I20: MONTAJE MN | J20: TECNICO MECANICO MONTAJISTA DE MAQUINARIA | K20: CORREA TORRES NOYLER | L20: 5ta | M20: 65 | N20: MECANOS | O20: 019 | W20: 43849 | X20: 1 | Y20: =TEXT(W20,"ddddd") -> domingo | AC20: 0.79166667
A21: 20 | B21: MAE6G-01 | C21: SOLDADURA | D21: MAESTRO SOLDADOR 6G MONTAJISTA DE MAQUINARIA | F21: =VLOOKUP(K21,DNI!$A$1:$B$10000,2,FALSE) -> 70133802 | G21: =H21&-O21 -> TEC-04-20 | H21: TEC-04 | I21: MONTAJE ME | J21: TECNICO MECANICO MONTAJISTA DE MAQUINARIA EXTRANJERA | K21: CUYA CAYCHO DANIEL LORENZO | L21: 5ta | M21: 66.92 | N21: MECANOS | O21: 020 | W21: 43850 | Y21: =TEXT(W21,"ddddd") -> lunes | AC21: 0.83333333
A22: 21 | B22: OPE-01 | C22: SOLDADURA | D22: OPERARIO SOLDADOR | F22: =VLOOKUP(K22,DNI!$A$1:$B$10000,2,FALSE) -> 42558469 | G22: =H22&-O22 -> OPE-01-21 | H22: OPE-01 | I22: SOLDADURA | J22: OPERARIO SOLDADOR | K22: ENRIQUEZ GONZALES MIGUEL ANGEL | L22: 4ta | M22: 60 | N22: MECANOS | O22: 021 | W22: 43851 | Y22: =TEXT(W22,"ddddd") -> martes | AC22: 0.875
A23: 22 | B23: TEC-01 | C23: SOLDADURA | D23: TECNICO SOLDADOR | F23: =VLOOKUP(K23,DNI!$A$1:$B$10000,2,FALSE) -> 73147673 | G23: =H23&-O23 -> OPE-01-22 | H23: OPE-01 | I23: SOLDADURA | J23: OPERARIO SOLDADOR | K23: ESPINOZA CHANAME DIEGO ARMANDO | L23: 5ta | M23: 55 | N23: MECANOS | O23: 022 | W23: 43852 | Y23: =TEXT(W23,"ddddd") -> miércoles | AC23: 0.91666667
A24: 23 | B24: AYU-VA | C24: VARIAS | D24: AYUDANTE DE PRODUCCION | F24: 47555533 | G24: =H24&-O24 -> TEC-02-23 | H24: TEC-02 | I24: MONTAJE MN | J24: TECNICO MECANICO MONTAJISTA DE MAQUINARIA | K24: FLORES TINEO JOSE ANGEL | L24: 4ta | M24: 60 | N24: MECANOS | O24: 023 | W24: 43853 | Y24: =TEXT(W24,"ddddd") -> jueves | AC24: 0.95833333
F25: =VLOOKUP(K25,DNI!$A$1:$B$10000,2,FALSE) -> 48046568 | G25: =H25&-O25 -> MAE-02-24 | H25: MAE-02 | I25: MONTAJE MN | J25: MAESTRO MECANICO MONTAJISTA DE MAQUINARIA | K25: GRAUS JUAREZ MIGUEL RICARDO | L25: 5ta | M25: 68.15 | N25: MECANOS | O25: 024 | W25: 43854 | Y25: =TEXT(W25,"ddddd") -> viernes | AC25: 1
F26: =VLOOKUP(K26,DNI!$A$1:$B$10000,2,FALSE) -> 45545014 | G26: =H26&-O26 -> TEC-01-25 | H26: TEC-01 | I26: SOLDADURA | J26: TECNICO SOLDADOR | K26: GUEVARA PACHERREZ ERICK DANIEL | L26: 4ta | M26: 60 | N26: MECANOS | O26: 025 | W26: 43855 | Y26: =TEXT(W26,"ddddd") -> sábado
F27: =VLOOKUP(K27,DNI!$A$1:$B$10000,2,FALSE) -> 70858509 | G27: =H27&-O27 -> TEC-01-26 | H27: TEC-01 | I27: SOLDADURA | J27: TECNICO SOLDADOR | K27: HUAMAN CAMPOS BRIAN ROY | L27: 4ta | M27: 60 | N27: MECANOS | O27: 026 | W27: 43856 | X27: 1 | Y27: =TEXT(W27,"ddddd") -> domingo
F28: =VLOOKUP(K28,DNI!$A$1:$B$10000,2,FALSE) -> 46228460 | G28: =H28&-O28 -> TEC-04-27 | H28: TEC-04 | I28: MONTAJE ME | J28: TECNICO MECANICO MONTAJISTA DE MAQUINARIA EXTRANJERA | K28: IDROGO CHAVEZ EMANUEL | L28: 5ta | M28: 67.66 | N28: MECANOS | O28: 027 | W28: 43857 | Y28: =TEXT(W28,"ddddd") -> lunes
F29: =VLOOKUP(K29,DNI!$A$1:$B$10000,2,FALSE) -> 47466045 | G29: =H29&-O29 -> MAE3G-01-28 | H29: MAE3G-01 | I29: SOLDADURA | J29: MAESTRO SOLDADOR 3G | K29: LABAN SEVERINO EDWIN DENIS | L29: 5ta | M29: 70.38 | N29: MECANOS | O29: 028 | W29: 43858 | Y29: =TEXT(W29,"ddddd") -> martes
F30: =VLOOKUP(K30,DNI!$A$1:$B$10000,2,FALSE) -> 62188868 | G30: =H30&-O30 -> AYU-VA-29 | H30: AYU-VA | I30: VARIAS | J30: AYUDANTE DE PRODUCCION | K30: LOPEZ TANTARICO ELY | L30: 5ta | M30: 39.15 | N30: MECANOS | O30: 029 | W30: 43859 | Y30: =TEXT(W30,"ddddd") -> miércoles
F31: =VLOOKUP(K31,DNI!$A$1:$B$10000,2,FALSE) -> 16792081 | G31: =H31&-O31 -> MAE3G-01-30 | H31: MAE3G-01 | I31: SOLDADURA | J31: MAESTRO SOLDADOR 3G | K31: MEDINA GUEVARA TIRSO | L31: 4ta | M31: 85 | N31: MECANOS | O31: 030 | W31: 43860 | Y31: =TEXT(W31,"ddddd") -> jueves
F32: =VLOOKUP(K32,DNI!$A$1:$B$10000,2,FALSE) -> 73541627 | G32: =H32&-O32 -> TEC-02-31 | H32: TEC-02 | I32: MONTAJE MN | J32: TECNICO MECANICO MONTAJISTA DE MAQUINARIA | K32: MEJIA AYALA LUIS MANUEL | L32: 5ta | M32: 55 | N32: MECANOS | O32: 031 | W32: 43861 | Y32: =TEXT(W32,"ddddd") -> viernes
F33: =VLOOKUP(K33,DNI!$A$1:$B$10000,2,FALSE) -> 76811302 | G33: =H33&-O33 -> TEC-04-32 | H33: TEC-04 | I33: MONTAJE ME | J33: TECNICO MECANICO MONTAJISTA DE MAQUINARIA EXTRANJERA | K33: MEREGILDO CABRERA RICARDO JOEL | L33: 5ta | M33: 60 | N33: MECANOS | O33: 032 | W33: 43862 | Y33: =TEXT(W33,"ddddd") -> sábado
F34: =VLOOKUP(K34,DNI!$A$1:$B$10000,2,FALSE) -> 76457697 | G34: =H34&-O34 -> AYU-VA-33 | H34: AYU-VA | I34: VARIAS | J34: AYUDANTE DE PRODUCCION | K34: MIO QUIÑONES ALEXIS | L34: 5ta | M34: 45 | N34: MECANOS | O34: 033 | W34: 43863 | X34: 1 | Y34: =TEXT(W34,"ddddd") -> domingo
F35: =VLOOKUP(K35,DNI!$A$1:$B$10000,2,FALSE) -> 47586740 | G35: =H35&-O35 -> TEC-02-34 | H35: TEC-02 | I35: MONTAJE MN | J35: TECNICO MECANICO MONTAJISTA DE MAQUINARIA | K35: MIO SOLUCO CESAR AUGUSTO | L35: 4ta | M35: 60 | N35: MECANOS | O35: 034 | W35: 43864 | Y35: =TEXT(W35,"ddddd") -> lunes
F36: =VLOOKUP(K36,DNI!$A$1:$B$10000,2,FALSE) -> 72241927 | G36: =H36&-O36 -> MAE-05-35 | H36: MAE-05 | I36: MONTAJE NAVE | J36: MAESTRO MECANICO MONTAJISTA DE NAVE INDUSTRIAL | K36: OJANAMA UTIA ENERLI HORACIO | L36: 5ta | M36: 70 | N36: MECANOS | O36: 035 | W36: 43865 | Y36: =TEXT(W36,"ddddd") -> martes
F37: =VLOOKUP(K37,DNI!$A$1:$B$10000,2,FALSE) -> 76785790 | G37: =H37&-O37 -> AYU-VA-36 | H37: AYU-VA | I37: VARIAS | J37: AYUDANTE DE PRODUCCION | K37: OJANAMA UTIA MARTIN SOLANO | L37: 4ta | M37: 45 | N37: MECANOS | O37: 036 | W37: 43866 | Y37: =TEXT(W37,"ddddd") -> miércoles
F38: =VLOOKUP(K38,DNI!$A$1:$B$10000,2,FALSE) -> 72241926 | G38: =H38&-O38 -> AYU-VA-37 | H38: AYU-VA | I38: VARIAS | J38: AYUDANTE DE PRODUCCION | K38: OJANAMA UTIA TEOFILO ALVINO | L38: 4ta | M38: 45 | N38: MECANOS | O38: 037 | W38: 43867 | Y38: =TEXT(W38,"ddddd") -> jueves
F39: =VLOOKUP(K39,DNI!$A$1:$B$10000,2,FALSE) -> 45821420 | G39: =H39&-O39 -> TEC-05-38 | H39: TEC-05 | I39: MONTAJE NAVE | J39: TECNICO MECANICO MONTAJISTA DE NAVE INDUSTRIAL | K39: ORTIZ PANTALEON POLH MANIX | L39: 5ta | M39: 56.55 | N39: MECANOS | O39: 038 | W39: 43868 | Y39: =TEXT(W39,"ddddd") -> viernes
F40: =VLOOKUP(K40,DNI!$A$1:$B$10000,2,FALSE) -> 47887505 | G40: =H40&-O40 -> TEC-01-39 | H40: TEC-01 | I40: SOLDADURA | J40: TECNICO SOLDADOR | K40: PANDO SALAZAR LUIS BRYAN | L40: 5ta | M40: 66.48 | N40: MECANOS | O40: 039 | W40: 43869 | Y40: =TEXT(W40,"ddddd") -> sábado
...

Sheet BD
AS1: 1 | AT1: PLANTA | AU1: 0.375 | AV1: L-V | AW1: 0.33333333 | AX1: 0.29166667 | AY1: S
M3: HORARIO | AS3: 2 | AT3: OBRA | AU3: 0.33333333 | AV3: L-S
N4: ALMUERZO | T4: MAGIA FIORELA | AF4: EXTRA | AH4: 4TA | AJ4: 5TA
A5: DIA | B5: PUNTO | C5: N° SEMANA | D5: N° MES | E5: CONDICION | F5: PERFIL | G5: DETALLE PERFIL | H5: TRABAJADOR | I5: FECHA | J5: DESTINO | K5: DNI | L5: DIARIO | M5: INGRESO | N5: INICIO | O5: FIN | P5: SALIDA | Q5: T.HORAS | R5: H.NORMALES | S5: H.EXTRAS | T5: HORAS 25 % | U5: HORAS 35% | V5: C.HORA.25 | W5: C.HORA.35 | X5: CST_H_E | Y5: C.H | Z5: T.H | AA5: H.N | AB5: H.E | AC5: COS.BASE 2 | AD5: COS.BASE 3 | AE5: COS.B+E | AF5: F | AG5: D | AH5: COS.F1 | AI5: COS.D1 | AJ5: COS F2 | AK5: COS D2 | AL5: ALIMENTACION | AM5: PRESTAMO | AN5: PASAJES | AO5: MONTO 4 TA | AP5: MONTO 5TA | AS5: 8 | AT5: OBRA | AU5: 0.33333333 | AV5: L-S
A6: =TEXT(Tabla1[[#This Row],[FECHA ]],"DDDDD") -> viernes | B6: =_xlfn.IFNA(VLOOKUP(Tabla1[[#This Row],[DESTINO]],RUBRO!$Q$1:$R$9996,2,FALSE)," ") -> PLANTA | C6: =WEEKNUM(Tabla1[[#This Row],[FECHA ]],2) -> 19 | D6: =TEXT(Tabla1[[#This Row],[FECHA ]],"MMM-YY") -> may-YY | E6: =VLOOKUP(Tabla1[[#This Row],[DNI ]],RUBRO!$F$1:$O$9996,7,FALSE) -> 5ta | F6: =VLOOKUP(Tabla1[[#This Row],[DNI ]],RUBRO!$F$1:$O$88,3,FALSE) -> TEC-02 | G6: =VLOOKUP(Tabla1[[#This Row],[DNI ]],RUBRO!$F$1:$O$9996,5,FALSE) -> TECNICO MECANICO MONTAJISTA DE MAQUINARIA | H6: =VLOOKUP(Tabla1[[#This Row],[DNI ]],RUBRO!$F$1:$O$9996,6,FALSE) -> ALVAREZ ALVINES JUAN MANUEL | I6: 44323 | J6: 1 | K6: 46108491 | L6: =VLOOKUP(Tabla1[[#This Row],[DNI ]],RUBRO!$F$2:$O$9996,8,FALSE) -> 50 | M6: 0.29166667 | N6: 0.54166667 | O6: 0.58333333 | P6: 0.70833333 | Q6: =(Tabla1[[#This Row],[SALIDA]]-Tabla1[[#This Row],[FIN ]])+(Tabla1[[#This Row],[INICIO]]-Tabla1[[#This Row],[INGRESO]]) -> 0.375 | R6: =IF(J6=1,IF(Q6>$AU$1,$AU$1,Q6),0)+IF(J6=2,IF(Q6>$AU$3,$AU$3,Q6),0)+IF(J6=8,IF(Q6>$AU$5,$AU$5,Q6),0) -> 0.375 | S6: =IF(J6=1,IF(Q6>$AU$1,(Q6-R6),0),0)+IF(J6=2,IF(Q6>$AU$3,(Q6-R6),0),0)+IF(J6=8,IF(Q6>$AU$5,(Q6-R6),0),0) -> 0 | V6: =(Tabla1[[#This Row],[COS.BASE 3]]*0.25+Tabla1[[#This Row],[COS.BASE 3]])*Tabla1[[#This Row],[HORAS 25 % ]] -> 0 | W6: =(Tabla1[[#This Row],[COS.BASE 3]]*0.35+Tabla1[[#This Row],[COS.BASE 3]])*Tabla1[[#This Row],[HORAS 35% ]] -> 0 | X6: =SUM(Tabla1[[#This Row],[C.HORA.35]],Tabla1[[#This Row],[C.HORA.25]]) -> 0 | Z6: =Tabla1[[#This Row],[T.HORAS]]*24 -> 9 | AA6: =Tabla1[[#This Row],[H.NORMALES]]*24 -> 9 | AB6: =Tabla1[[#This Row],[H.EXTRAS]]*24 -> 0 | AC6: =IF(J6=1,(((R6*24)*(L6/9))),0)+IF(J6=2,(((R6*24)*(L6/8))),0)+IF(J6=8,(((R6*24)*(L6/8))),0) -> 50 | AD6: =Tabla1[[#This Row],[COS.BASE 2]]/8 -> 6.25 | AE6: =Tabla1[[#This Row],[CST_H_E]]+Tabla1[[#This Row],[COS.BASE 2]] -> 50 | AF6: =+_xlfn.IFNA(INDEX(RUBRO!$W$2:$AA$732,MATCH(Tabla1[[#This Row],[FECHA ]],RUBRO!$W$2:$W$732,0),5)," ") -> 0 | AG6: =+_xlfn.IFNA(INDEX(RUBRO!$W$2:$AA$732,MATCH(Tabla1[[#This Row],[FECHA ]],RUBRO!$W$2:$W$732,0),2)," ") -> 0 | AH6: =IFERROR(Tabla1[[#This Row],[F]]*Tabla1[[#This Row],[COS.B+E]]," ") -> 0 | AI6: =IFERROR(Tabla1[[#This Row],[COS.B+E]]*Tabla1[[#This Row],[D]]," ") -> 0 | AJ6: =IFERROR(Tabla1[[#This Row],[F]]*#REF!," ") | AK6: =IFERROR(#REF!*Tabla1[[#This Row],[D]]," ") | AO6: =+Tabla1[[#This Row],[COS.B+E]]+Tabla1[[#This Row],[COS.F1]]+Tabla1[[#This Row],[COS.D1]]+Tabla1[[#This Row],[ALIMENTACION]]+Tabla1[[#This Row],[PRESTAMO]]+AN6 -> 50 | AP6: =+#REF!+Tabla1[[#This Row],[COS F2]]+Tabla1[[#This Row],[COS D2]]+Tabla1[[#This Row],[ALIMENTACION]]+Tabla1[[#This Row],[PRESTAMO]]+Tabla1[[#This Row],[PASAJES]] -> #REF!
A7: =TEXT(Tabla1[[#This Row],[FECHA ]],"DDDDD") -> viernes | B7: =_xlfn.IFNA(VLOOKUP(Tabla1[[#This Row],[DESTINO]],RUBRO!$Q$1:$R$9996,2,FALSE)," ") -> PLANTA | C7: =WEEKNUM(Tabla1[[#This Row],[FECHA ]],2) -> 19 | D7: =TEXT(Tabla1[[#This Row],[FECHA ]],"MMM-YY") -> may-YY | E7: =VLOOKUP(Tabla1[[#This Row],[DNI ]],RUBRO!$F$1:$O$9996,7,FALSE) -> 4ta | F7: =VLOOKUP(Tabla1[[#This Row],[DNI ]],RUBRO!$F$1:$O$88,3,FALSE) -> OPE-03 | G7: =VLOOKUP(Tabla1[[#This Row],[DNI ]],RUBRO!$F$1:$O$9996,5,FALSE) -> OPERARIO ELECTRICO | H7: =VLOOKUP(Tabla1[[#This Row],[DNI ]],RUBRO!$F$1:$O$9996,6,FALSE) -> AYALA RAMIREZ RUBEN ISAI | I7: 44323 | J7: 1 | K7: 75557820 | L7: =VLOOKUP(Tabla1[[#This Row],[DNI ]],RUBRO!$F$2:$O$9996,8,FALSE) -> 50 | M7: 0.29166667 | N7: 0.54166667 | O7: 0.58333333 | P7: 0.70833333 | Q7: =(Tabla1[[#This Row],[SALIDA]]-Tabla1[[#This Row],[FIN ]])+(Tabla1[[#This Row],[INICIO]]-Tabla1[[#This Row],[INGRESO]]) -> 0.375 | R7: =IF(J7=1,IF(Q7>$AU$1,$AU$1,Q7),0)+IF(J7=2,IF(Q7>$AU$3,$AU$3,Q7),0)+IF(J7=8,IF(Q7>$AU$5,$AU$5,Q7),0) -> 0.375 | S7: =IF(J7=1,IF(Q7>$AU$1,(Q7-R7),0),0)+IF(J7=2,IF(Q7>$AU$3,(Q7-R7),0),0)+IF(J7=8,IF(Q7>$AU$5,(Q7-R7),0),0) -> 0 | V7: =(Tabla1[[#This Row],[COS.BASE 3]]*0.25+Tabla1[[#This Row],[COS.BASE 3]])*Tabla1[[#This Row],[HORAS 25 % ]] -> 0 | W7: =(Tabla1[[#This Row],[COS.BASE 3]]*0.35+Tabla1[[#This Row],[COS.BASE 3]])*Tabla1[[#This Row],[HORAS 35% ]] -> 0 | X7: =SUM(Tabla1[[#This Row],[C.HORA.35]],Tabla1[[#This Row],[C.HORA.25]]) -> 0 | Z7: =Tabla1[[#This Row],[T.HORAS]]*24 -> 9 | AA7: =Tabla1[[#This Row],[H.NORMALES]]*24 -> 9 | AB7: =Tabla1[[#This Row],[H.EXTRAS]]*24 -> 0 | AC7: =IF(J7=1,(((R7*24)*(L7/9))),0)+IF(J7=2,(((R7*24)*(L7/8))),0)+IF(J7=8,(((R7*24)*(L7/8))),0) -> 50 | AD7: =Tabla1[[#This Row],[COS.BASE 2]]/8 -> 6.25 | AE7: =Tabla1[[#This Row],[CST_H_E]]+Tabla1[[#This Row],[COS.BASE 2]] -> 50 | AF7: =+_xlfn.IFNA(INDEX(RUBRO!$W$2:$AA$732,MATCH(Tabla1[[#This Row],[FECHA ]],RUBRO!$W$2:$W$732,0),5)," ") -> 0 | AG7: =+_xlfn.IFNA(INDEX(RUBRO!$W$2:$AA$732,MATCH(Tabla1[[#This Row],[FECHA ]],RUBRO!$W$2:$W$732,0),2)," ") -> 0 | AH7: =IFERROR(Tabla1[[#This Row],[F]]*Tabla1[[#This Row],[COS.B+E]]," ") -> 0 | AI7: =IFERROR(Tabla1[[#This Row],[COS.B+E]]*Tabla1[[#This Row],[D]]," ") -> 0 | AJ7: =IFERROR(Tabla1[[#This Row],[F]]*#REF!," ") | AK7: =IFERROR(#REF!*Tabla1[[#This Row],[D]]," ") | AO7: =+Tabla1[[#This Row],[COS.B+E]]+Tabla1[[#This Row],[COS.F1]]+Tabla1[[#This Row],[COS.D1]]+Tabla1[[#This Row],[ALIMENTACION]]+Tabla1[[#This Row],[PRESTAMO]]+AN7 -> 50 | AP7: =+#REF!+Tabla1[[#This Row],[COS F2]]+Tabla1[[#This Row],[COS D2]]+Tabla1[[#This Row],[ALIMENTACION]]+Tabla1[[#This Row],[PRESTAMO]]+Tabla1[[#This Row],[PASAJES]] -> #REF!
A8: =TEXT(Tabla1[[#This Row],[FECHA ]],"DDDDD") -> viernes | B8: =_xlfn.IFNA(VLOOKUP(Tabla1[[#This Row],[DESTINO]],RUBRO!$Q$1:$R$9996,2,FALSE)," ") -> OBRA | C8: =WEEKNUM(Tabla1[[#This Row],[FECHA ]],2) -> 19 | D8: =TEXT(Tabla1[[#This Row],[FECHA ]],"MMM-YY") -> may-YY | E8: =VLOOKUP(Tabla1[[#This Row],[DNI ]],RUBRO!$F$1:$O$9996,7,FALSE) -> 5ta | F8: =VLOOKUP(Tabla1[[#This Row],[DNI ]],RUBRO!$F$1:$O$88,3,FALSE) -> OPE-03 | G8: =VLOOKUP(Tabla1[[#This Row],[DNI ]],RUBRO!$F$1:$O$9996,5,FALSE) -> OPERARIO ELECTRICO | H8: =VLOOKUP(Tabla1[[#This Row],[DNI ]],RUBRO!$F$1:$O$9996,6,FALSE) -> BARRAGAN SALAZAR JHONATAN PEDRO | I8: 44323 | J8: 2 | K8: 46801821 | L8: =VLOOKUP(Tabla1[[#This Row],[DNI ]],RUBRO!$F$2:$O$9996,8,FALSE) -> 43.5 | M8: 0.29166667 | N8: 0.54166667 | O8: 0.58333333 | P8: 0.75 | Q8: =(Tabla1[[#This Row],[SALIDA]]-Tabla1[[#This Row],[FIN ]])+(Tabla1[[#This Row],[INICIO]]-Tabla1[[#This Row],[INGRESO]]) -> 0.41666667 | R8: =IF(J8=1,IF(Q8>$AU$1,$AU$1,Q8),0)+IF(J8=2,IF(Q8>$AU$3,$AU$3,Q8),0)+IF(J8=8,IF(Q8>$AU$5,$AU$5,Q8),0) -> 0.33333333 | S8: =IF(J8=1,IF(Q8>$AU$1,(Q8-R8),0),0)+IF(J8=2,IF(Q8>$AU$3,(Q8-R8),0),0)+IF(J8=8,IF(Q8>$AU$5,(Q8-R8),0),0) -> 0.083333333 | T8: 1 | U8: 1 | V8: =(Tabla1[[#This Row],[COS.BASE 3]]*0.25+Tabla1[[#This Row],[COS.BASE 3]])*Tabla1[[#This Row],[HORAS 25 % ]] -> 6.796875 | W8: =(Tabla1[[#This Row],[COS.BASE 3]]*0.35+Tabla1[[#This Row],[COS.BASE 3]])*Tabla1[[#This Row],[HORAS 35% ]] -> 7.340625 | X8: =SUM(Tabla1[[#This Row],[C.HORA.35]],Tabla1[[#This Row],[C.HORA.25]]) -> 14.1375 | Z8: =Tabla1[[#This Row],[T.HORAS]]*24 -> 10 | AA8: =Tabla1[[#This Row],[H.NORMALES]]*24 -> 8 | AB8: =Tabla1[[#This Row],[H.EXTRAS]]*24 -> 2 | AC8: =IF(J8=1,(((R8*24)*(L8/9))),0)+IF(J8=2,(((R8*24)*(L8/8))),0)+IF(J8=8,(((R8*24)*(L8/8))),0) -> 43.5 | AD8: =Tabla1[[#This Row],[COS.BASE 2]]/8 -> 5.4375 | AE8: =Tabla1[[#This Row],[CST_H_E]]+Tabla1[[#This Row],[COS.BASE 2]] -> 57.6375 | AF8: =+_xlfn.IFNA(INDEX(RUBRO!$W$2:$AA$732,MATCH(Tabla1[[#This Row],[FECHA ]],RUBRO!$W$2:$W$732,0),5)," ") -> 0 | AG8: =+_xlfn.IFNA(INDEX(RUBRO!$W$2:$AA$732,MATCH(Tabla1[[#This Row],[FECHA ]],RUBRO!$W$2:$W$732,0),2)," ") -> 0 | AH8: =IFERROR(Tabla1[[#This Row],[F]]*Tabla1[[#This Row],[COS.B+E]]," ") -> 0 | AI8: =IFERROR(Tabla1[[#This Row],[COS.B+E]]*Tabla1[[#This Row],[D]]," ") -> 0 | AJ8: =IFERROR(Tabla1[[#This Row],[F]]*#REF!," ") | AK8: =IFERROR(#REF!*Tabla1[[#This Row],[D]]," ") | AO8: =+Tabla1[[#This Row],[COS.B+E]]+Tabla1[[#This Row],[COS.F1]]+Tabla1[[#This Row],[COS.D1]]+Tabla1[[#This Row],[ALIMENTACION]]+Tabla1[[#This Row],[PRESTAMO]]+AN8 -> 57.6375 | AP8: =+#REF!+Tabla1[[#This Row],[COS F2]]+Tabla1[[#This Row],[COS D2]]+Tabla1[[#This Row],[ALIMENTACION]]+Tabla1[[#This Row],[PRESTAMO]]+Tabla1[[#This Row],[PASAJES]] -> #REF!
A9: =TEXT(Tabla1[[#This Row],[FECHA ]],"DDDDD") -> viernes | B9: =_xlfn.IFNA(VLOOKUP(Tabla1[[#This Row],[DESTINO]],RUBRO!$Q$1:$R$9996,2,FALSE)," ") -> PLANTA | C9: =WEEKNUM(Tabla1[[#This Row],[FECHA ]],2) -> 19 | D9: =TEXT(Tabla1[[#This Row],[FECHA ]],"MMM-YY") -> may-YY | E9: =VLOOKUP(Tabla1[[#This Row],[DNI ]],RUBRO!$F$1:$O$9996,7,FALSE) -> 5ta | F9: =VLOOKUP(Tabla1[[#This Row],[DNI ]],RUBRO!$F$1:$O$88,3,FALSE) -> OPE-01 | G9: =VLOOKUP(Tabla1[[#This Row],[DNI ]],RUBRO!$F$1:$O$9996,5,FALSE) -> OPERARIO SOLDADOR | H9: =VLOOKUP(Tabla1[[#This Row],[DNI ]],RUBRO!$F$1:$O$9996,6,FALSE) -> BENDEZU PISCO JORGE GUILLERMO | I9: 44323 | J9: 1 | K9: 10664396 | L9: =VLOOKUP(Tabla1[[#This Row],[DNI ]],RUBRO!$F$2:$O$9996,8,FALSE) -> 60 | M9: 0.29166667 | N9: 0.54166667 | O9: 0.58333333 | P9: 0.70833333 | Q9: =(Tabla1[[#This Row],[SALIDA]]-Tabla1[[#This Row],[FIN ]])+(Tabla1[[#This Row],[INICIO]]-Tabla1[[#This Row],[INGRESO]]) -> 0.375 | R9: =IF(J9=1,IF(Q9>$AU$1,$AU$1,Q9),0)+IF(J9=2,IF(Q9>$AU$3,$AU$3,Q9),0)+IF(J9=8,IF(Q9>$AU$5,$AU$5,Q9),0) -> 0.375 | S9: =IF(J9=1,IF(Q9>$AU$1,(Q9-R9),0),0)+IF(J9=2,IF(Q9>$AU$3,(Q9-R9),0),0)+IF(J9=8,IF(Q9>$AU$5,(Q9-R9),0),0) -> 0 | V9: =(Tabla1[[#This Row],[COS.BASE 3]]*0.25+Tabla1[[#This Row],[COS.BASE 3]])*Tabla1[[#This Row],[HORAS 25 % ]] -> 0 | W9: =(Tabla1[[#This Row],[COS.BASE 3]]*0.35+Tabla1[[#This Row],[COS.BASE 3]])*Tabla1[[#This Row],[HORAS 35% ]] -> 0 | X9: =SUM(Tabla1[[#This Row],[C.HORA.35]],Tabla1[[#This Row],[C.HORA.25]]) -> 0 | Z9: =Tabla1[[#This Row],[T.HORAS]]*24 -> 9 | AA9: =Tabla1[[#This Row],[H.NORMALES]]*24 -> 9 | AB9: =Tabla1[[#This Row],[H.EXTRAS]]*24 -> 0 | AC9: =IF(J9=1,(((R9*24)*(L9/9))),0)+IF(J9=2,(((R9*24)*(L9/8))),0)+IF(J9=8,(((R9*24)*(L9/8))),0) -> 60 | AD9: =Tabla1[[#This Row],[COS.BASE 2]]/8 -> 7.5 | AE9: =Tabla1[[#This Row],[CST_H_E]]+Tabla1[[#This Row],[COS.BASE 2]] -> 60 | AF9: =+_xlfn.IFNA(INDEX(RUBRO!$W$2:$AA$732,MATCH(Tabla1[[#This Row],[FECHA ]],RUBRO!$W$2:$W$732,0),5)," ") -> 0 | AG9: =+_xlfn.IFNA(INDEX(RUBRO!$W$2:$AA$732,MATCH(Tabla1[[#This Row],[FECHA ]],RUBRO!$W$2:$W$732,0),2)," ") -> 0 | AH9: =IFERROR(Tabla1[[#This Row],[F]]*Tabla1[[#This Row],[COS.B+E]]," ") -> 0 | AI9: =IFERROR(Tabla1[[#This Row],[COS.B+E]]*Tabla1[[#This Row],[D]]," ") -> 0 | AJ9: =IFERROR(Tabla1[[#This Row],[F]]*#REF!," ") | AK9: =IFERROR(#REF!*Tabla1[[#This Row],[D]]," ") | AO9: =+Tabla1[[#This Row],[COS.B+E]]+Tabla1[[#This Row],[COS.F1]]+Tabla1[[#This Row],[COS.D1]]+Tabla1[[#This Row],[ALIMENTACION]]+Tabla1[[#This Row],[PRESTAMO]]+AN9 -> 60 | AP9: =+#REF!+Tabla1[[#This Row],[COS F2]]+Tabla1[[#This Row],[COS D2]]+Tabla1[[#This Row],[ALIMENTACION]]+Tabla1[[#This Row],[PRESTAMO]]+Tabla1[[#This Row],[PASAJES]] -> #REF!
A10: =TEXT(Tabla1[[#This Row],[FECHA ]],"DDDDD") -> viernes | B10: =_xlfn.IFNA(VLOOKUP(Tabla1[[#This Row],[DESTINO]],RUBRO!$Q$1:$R$9996,2,FALSE)," ") -> FALTA | C10: =WEEKNUM(Tabla1[[#This Row],[FECHA ]],2) -> 19 | D10: =TEXT(Tabla1[[#This Row],[FECHA ]],"MMM-YY") -> may-YY | E10: =VLOOKUP(Tabla1[[#This Row],[DNI ]],RUBRO!$F$1:$O$9996,7,FALSE) -> 4ta | F10: =VLOOKUP(Tabla1[[#This Row],[DNI ]],RUBRO!$F$1:$O$88,3,FALSE) -> OPE-01 | G10: =VLOOKUP(Tabla1[[#This Row],[DNI ]],RUBRO!$F$1:$O$9996,5,FALSE) -> OPERARIO SOLDADOR | H10: =VLOOKUP(Tabla1[[#This Row],[DNI ]],RUBRO!$F$1:$O$9996,6,FALSE) -> BONILLA CHAVEZ LUIS DANIEL | I10: 44323 | J10: 4 | K10: 71995358 | L10: =VLOOKUP(Tabla1[[#This Row],[DNI ]],RUBRO!$F$2:$O$9996,8,FALSE) -> 45 | Q10: =(Tabla1[[#This Row],[SALIDA]]-Tabla1[[#This Row],[FIN ]])+(Tabla1[[#This Row],[INICIO]]-Tabla1[[#This Row],[INGRESO]]) -> 0 | R10: =IF(J10=1,IF(Q10>$AU$1,$AU$1,Q10),0)+IF(J10=2,IF(Q10>$AU$3,$AU$3,Q10),0)+IF(J10=8,IF(Q10>$AU$5,$AU$5,Q10),0) -> 0 | S10: =IF(J10=1,IF(Q10>$AU$1,(Q10-R10),0),0)+IF(J10=2,IF(Q10>$AU$3,(Q10-R10),0),0)+IF(J10=8,IF(Q10>$AU$5,(Q10-R10),0),0) -> 0 | V10: =(Tabla1[[#This Row],[COS.BASE 3]]*0.25+Tabla1[[#This Row],[COS.BASE 3]])*Tabla1[[#This Row],[HORAS 25 % ]] -> 0 | W10: =(Tabla1[[#This Row],[COS.BASE 3]]*0.35+Tabla1[[#This Row],[COS.BASE 3]])*Tabla1[[#This Row],[HORAS 35% ]] -> 0 | X10: =SUM(Tabla1[[#This Row],[C.HORA.35]],Tabla1[[#This Row],[C.HORA.25]]) -> 0 | Z10: =Tabla1[[#This Row],[T.HORAS]]*24 -> 0 | AA10: =Tabla1[[#This Row],[H.NORMALES]]*24 -> 0 | AB10: =Tabla1[[#This Row],[H.EXTRAS]]*24 -> 0 | AC10: =IF(J10=1,(((R10*24)*(L10/9))),0)+IF(J10=2,(((R10*24)*(L10/8))),0)+IF(J10=8,(((R10*24)*(L10/8))),0) -> 0 | AD10: =Tabla1[[#This Row],[COS.BASE 2]]/8 -> 0 | AE10: =Tabla1[[#This Row],[CST_H_E]]+Tabla1[[#This Row],[COS.BASE 2]] -> 0 | AF10: =+_xlfn.IFNA(INDEX(RUBRO!$W$2:$AA$732,MATCH(Tabla1[[#This Row],[FECHA ]],RUBRO!$W$2:$W$732,0),5)," ") -> 0 | AG10: =+_xlfn.IFNA(INDEX(RUBRO!$W$2:$AA$732,MATCH(Tabla1[[#This Row],[FECHA ]],RUBRO!$W$2:$W$732,0),2)," ") -> 0 | AH10: =IFERROR(Tabla1[[#This Row],[F]]*Tabla1[[#This Row],[COS.B+E]]," ") -> 0 | AI10: =IFERROR(Tabla1[[#This Row],[COS.B+E]]*Tabla1[[#This Row],[D]]," ") -> 0 | AJ10: =IFERROR(Tabla1[[#This Row],[F]]*#REF!," ") | AK10: =IFERROR(#REF!*Tabla1[[#This Row],[D]]," ") | AO10: =+Tabla1[[#This Row],[COS.B+E]]+Tabla1[[#This Row],[COS.F1]]+Tabla1[[#This Row],[COS.D1]]+Tabla1[[#This Row],[ALIMENTACION]]+Tabla1[[#This Row],[PRESTAMO]]+AN10 -> 0 | AP10: =+#REF!+Tabla1[[#This Row],[COS F2]]+Tabla1[[#This Row],[COS D2]]+Tabla1[[#This Row],[ALIMENTACION]]+Tabla1[[#This Row],[PRESTAMO]]+Tabla1[[#This Row],[PASAJES]] -> #REF!
A11: =TEXT(Tabla1[[#This Row],[FECHA ]],"DDDDD") -> viernes | B11: =_xlfn.IFNA(VLOOKUP(Tabla1[[#This Row],[DESTINO]],RUBRO!$Q$1:$R$9996,2,FALSE)," ") -> OBRA | C11: =WEEKNUM(Tabla1[[#This Row],[FECHA ]],2) -> 19 | D11: =TEXT(Tabla1[[#This Row],[FECHA ]],"MMM-YY") -> may-YY | E11: =VLOOKUP(Tabla1[[#This Row],[DNI ]],RUBRO!$F$1:$O$9996,7,FALSE) -> 5ta | F11: =VLOOKUP(Tabla1[[#This Row],[DNI ]],RUBRO!$F$1:$O$88,3,FALSE) -> MEC-04 | G11: =VLOOKUP(Tabla1[[#This Row],[DNI ]],RUBRO!$F$1:$O$9996,5,FALSE) -> MECANICO MONTAJISTA DE MAQUINARIA EXTRANJERA | H11: =VLOOKUP(Tabla1[[#This Row],[DNI ]],RUBRO!$F$1:$O$9996,6,FALSE) -> BUSTAMANTE GONZALES CARLOS | I11: 44323 | J11: 2 | K11: 27291529 | L11: =VLOOKUP(Tabla1[[#This Row],[DNI ]],RUBRO!$F$2:$O$9996,8,FALSE) -> 72.54 | M11: 0.29166667 | N11: 0.54166667 | O11: 0.58333333 | P11: 0.75 | Q11: =(Tabla1[[#This Row],[SALIDA]]-Tabla1[[#This Row],[FIN ]])+(Tabla1[[#This Row],[INICIO]]-Tabla1[[#This Row],[INGRESO]]) -> 0.41666667 | R11: =IF(J11=1,IF(Q11>$AU$1,$AU$1,Q11),0)+IF(J11=2,IF(Q11>$AU$3,$AU$3,Q11),0)+IF(J11=8,IF(Q11>$AU$5,$AU$5,Q11),0) -> 0.33333333 | S11: =IF(J11=1,IF(Q11>$AU$1,(Q11-R11),0),0)+IF(J11=2,IF(Q11>$AU$3,(Q11-R11),0),0)+IF(J11=8,IF(Q11>$AU$5,(Q11-R11),0),0) -> 0.083333333 | V11: =(Tabla1[[#This Row],[COS.BASE 3]]*0.25+Tabla1[[#This Row],[COS.BASE 3]])*Tabla1[[#This Row],[HORAS 25 % ]] -> 0 | W11: =(Tabla1[[#This Row],[COS.BASE 3]]*0.35+Tabla1[[#This Row],[COS.BASE 3]])*Tabla1[[#This Row],[HORAS 35% ]] -> 0 | X11: =SUM(Tabla1[[#This Row],[C.HORA.35]],Tabla1[[#This Row],[C.HORA.25]]) -> 0 | Z11: =Tabla1[[#This Row],[T.HORAS]]*24 -> 10 | AA11: =Tabla1[[#This Row],[H.NORMALES]]*24 -> 8 | AB11: =Tabla1[[#This Row],[H.EXTRAS]]*24 -> 2 | AC11: =IF(J11=1,(((R11*24)*(L11/9))),0)+IF(J11=2,(((R11*24)*(L11/8))),0)+IF(J11=8,(((R11*24)*(L11/8))),0) -> 72.54 | AD11: =Tabla1[[#This Row],[COS.BASE 2]]/8 -> 9.0675 | AE11: =Tabla1[[#This Row],[CST_H_E]]+Tabla1[[#This Row],[COS.BASE 2]] -> 72.54 | AF11: =+_xlfn.IFNA(INDEX(RUBRO!$W$2:$AA$732,MATCH(Tabla1[[#This Row],[FECHA ]],RUBRO!$W$2:$W$732,0),5)," ") -> 0 | AG11: =+_xlfn.IFNA(INDEX(RUBRO!$W$2:$AA$732,MATCH(Tabla1[[#This Row],[FECHA ]],RUBRO!$W$2:$W$732,0),2)," ") -> 0 | AH11: =IFERROR(Tabla1[[#This Row],[F]]*Tabla1[[#This Row],[COS.B+E]]," ") -> 0 | AI11: =IFERROR(Tabla1[[#This Row],[COS.B+E]]*Tabla1[[#This Row],[D]]," ") -> 0 | AJ11: =IFERROR(Tabla1[[#This Row],[F]]*#REF!," ") | AK11: =IFERROR(#REF!*Tabla1[[#This Row],[D]]," ") | AO11: =+Tabla1[[#This Row],[COS.B+E]]+Tabla1[[#This Row],[COS.F1]]+Tabla1[[#This Row],[COS.D1]]+Tabla1[[#This Row],[ALIMENTACION]]+Tabla1[[#This Row],[PRESTAMO]]+AN11 -> 72.54 | AP11: =+#REF!+Tabla1[[#This Row],[COS F2]]+Tabla1[[#This Row],[COS D2]]+Tabla1[[#This Row],[ALIMENTACION]]+Tabla1[[#This Row],[PRESTAMO]]+Tabla1[[#This Row],[PASAJES]] -> #REF!
A12: =TEXT(Tabla1[[#This Row],[FECHA ]],"DDDDD") -> viernes | B12: =_xlfn.IFNA(VLOOKUP(Tabla1[[#This Row],[DESTINO]],RUBRO!$Q$1:$R$9996,2,FALSE)," ") -> PLANTA | C12: =WEEKNUM(Tabla1[[#This Row],[FECHA ]],2) -> 19 | D12: =TEXT(Tabla1[[#This Row],[FECHA ]],"MMM-YY") -> may-YY | E12: =VLOOKUP(Tabla1[[#This Row],[DNI ]],RUBRO!$F$1:$O$9996,7,FALSE) -> 5ta | F12: =VLOOKUP(Tabla1[[#This Row],[DNI ]],RUBRO!$F$1:$O$88,3,FALSE) -> TECMN-03 | G12: =VLOOKUP(Tabla1[[#This Row],[DNI ]],RUBRO!$F$1:$O$9996,5,FALSE) -> TECNICO ELECTRICO MONTAJISTA DE MAQUINARIA | H12: =VLOOKUP(Tabla1[[#This Row],[DNI ]],RUBRO!$F$1:$O$9996,6,FALSE) -> CAMIZAN CUNIAS LENDER NEYDEN | I12: 44323 | J12: 1 | K12: 47711616 | L12: =VLOOKUP(Tabla1[[#This Row],[DNI ]],RUBRO!$F$2:$O$9996,8,FALSE) -> 47.73 | M12: 0.29166667 | N12: 0.54166667 | O12: 0.58333333 | P12: 0.70833333 | Q12: =(Tabla1[[#This Row],[SALIDA]]-Tabla1[[#This Row],[FIN ]])+(Tabla1[[#This Row],[INICIO]]-Tabla1[[#This Row],[INGRESO]]) -> 0.375 | R12: =IF(J12=1,IF(Q12>$AU$1,$AU$1,Q12),0)+IF(J12=2,IF(Q12>$AU$3,$AU$3,Q12),0)+IF(J12=8,IF(Q12>$AU$5,$AU$5,Q12),0) -> 0.375 | S12: =IF(J12=1,IF(Q12>$AU$1,(Q12-R12),0),0)+IF(J12=2,IF(Q12>$AU$3,(Q12-R12),0),0)+IF(J12=8,IF(Q12>$AU$5,(Q12-R12),0),0) -> 0 | V12: =(Tabla1[[#This Row],[COS.BASE 3]]*0.25+Tabla1[[#This Row],[COS.BASE 3]])*Tabla1[[#This Row],[HORAS 25 % ]] -> 0 | W12: =(Tabla1[[#This Row],[COS.BASE 3]]*0.35+Tabla1[[#This Row],[COS.BASE 3]])*Tabla1[[#This Row],[HORAS 35% ]] -> 0 | X12: =SUM(Tabla1[[#This Row],[C.HORA.35]],Tabla1[[#This Row],[C.HORA.25]]) -> 0 | Z12: =Tabla1[[#This Row],[T.HORAS]]*24 -> 9 | AA12: =Tabla1[[#This Row],[H.NORMALES]]*24 -> 9 | AB12: =Tabla1[[#This Row],[H.EXTRAS]]*24 -> 0 | AC12: =IF(J12=1,(((R12*24)*(L12/9))),0)+IF(J12=2,(((R12*24)*(L12/8))),0)+IF(J12=8,(((R12*24)*(L12/8))),0) -> 47.73 | AD12: =Tabla1[[#This Row],[COS.BASE 2]]/8 -> 5.96625 | AE12: =Tabla1[[#This Row],[CST_H_E]]+Tabla1[[#This Row],[COS.BASE 2]] -> 47.73 | AF12: =+_xlfn.IFNA(INDEX(RUBRO!$W$2:$AA$732,MATCH(Tabla1[[#This Row],[FECHA ]],RUBRO!$W$2:$W$732,0),5)," ") -> 0 | AG12: =+_xlfn.IFNA(INDEX(RUBRO!$W$2:$AA$732,MATCH(Tabla1[[#This Row],[FECHA ]],RUBRO!$W$2:$W$732,0),2)," ") -> 0 | AH12: =IFERROR(Tabla1[[#This Row],[F]]*Tabla1[[#This Row],[COS.B+E]]," ") -> 0 | AI12: =IFERROR(Tabla1[[#This Row],[COS.B+E]]*Tabla1[[#This Row],[D]]," ") -> 0 | AJ12: =IFERROR(Tabla1[[#This Row],[F]]*#REF!," ") | AK12: =IFERROR(#REF!*Tabla1[[#This Row],[D]]," ") | AO12: =+Tabla1[[#This Row],[COS.B+E]]+Tabla1[[#This Row],[COS.F1]]+Tabla1[[#This Row],[COS.D1]]+Tabla1[[#This Row],[ALIMENTACION]]+Tabla1[[#This Row],[PRESTAMO]]+AN12 -> 47.73 | AP12: =+#REF!+Tabla1[[#This Row],[COS F2]]+Tabla1[[#This Row],[COS D2]]+Tabla1[[#This Row],[ALIMENTACION]]+Tabla1[[#This Row],[PRESTAMO]]+Tabla1[[#This Row],[PASAJES]] -> #REF!
A13: =TEXT(Tabla1[[#This Row],[FECHA ]],"DDDDD") -> viernes | B13: =_xlfn.IFNA(VLOOKUP(Tabla1[[#This Row],[DESTINO]],RUBRO!$Q$1:$R$9996,2,FALSE)," ") -> OBRA | C13: =WEEKNUM(Tabla1[[#This Row],[FECHA ]],2) -> 19 | D13: =TEXT(Tabla1[[#This Row],[FECHA ]],"MMM-YY") -> may-YY | E13: =VLOOKUP(Tabla1[[#This Row],[DNI ]],RUBRO!$F$1:$O$9996,7,FALSE) -> 5ta | F13: =VLOOKUP(Tabla1[[#This Row],[DNI ]],RUBRO!$F$1:$O$88,3,FALSE) -> TEC-05 | G13: =VLOOKUP(Tabla1[[#This Row],[DNI ]],RUBRO!$F$1:$O$9996,5,FALSE) -> TECNICO MECANICO MONTAJISTA DE NAVE INDUSTRIAL | H13: =VLOOKUP(Tabla1[[#This Row],[DNI ]],RUBRO!$F$1:$O$9996,6,FALSE) -> CAVERO ANCAJIMA JHONATAN | I13: 44323 | J13: 2 | K13: 48237026 | L13: =VLOOKUP(Tabla1[[#This Row],[DNI ]],RUBRO!$F$2:$O$9996,8,FALSE) -> 52.2 | M13: 0.29166667 | N13: 0.54166667 | O13: 0.58333333 | P13: 0.75 | Q13: =(Tabla1[[#This Row],[SALIDA]]-Tabla1[[#This Row],[FIN ]])+(Tabla1[[#This Row],[INICIO]]-Tabla1[[#This Row],[INGRESO]]) -> 0.41666667 | R13: =IF(J13=1,IF(Q13>$AU$1,$AU$1,Q13),0)+IF(J13=2,IF(Q13>$AU$3,$AU$3,Q13),0)+IF(J13=8,IF(Q13>$AU$5,$AU$5,Q13),0) -> 0.33333333 | S13: =IF(J13=1,IF(Q13>$AU$1,(Q13-R13),0),0)+IF(J13=2,IF(Q13>$AU$3,(Q13-R13),0),0)+IF(J13=8,IF(Q13>$AU$5,(Q13-R13),0),0) -> 0.083333333 | V13: =(Tabla1[[#This Row],[COS.BASE 3]]*0.25+Tabla1[[#This Row],[COS.BASE 3]])*Tabla1[[#This Row],[HORAS 25 % ]] -> 0 | W13: =(Tabla1[[#This Row],[COS.BASE 3]]*0.35+Tabla1[[#This Row],[COS.BASE 3]])*Tabla1[[#This Row],[HORAS 35% ]] -> 0 | X13: =SUM(Tabla1[[#This Row],[C.HORA.35]],Tabla1[[#This Row],[C.HORA.25]]) -> 0 | Z13: =Tabla1[[#This Row],[T.HORAS]]*24 -> 10 | AA13: =Tabla1[[#This Row],[H.NORMALES]]*24 -> 8 | AB13: =Tabla1[[#This Row],[H.EXTRAS]]*24 -> 2 | AC13: =IF(J13=1,(((R13*24)*(L13/9))),0)+IF(J13=2,(((R13*24)*(L13/8))),0)+IF(J13=8,(((R13*24)*(L13/8))),0) -> 52.2 | AD13: =Tabla1[[#This Row],[COS.BASE 2]]/8 -> 6.525 | AE13: =Tabla1[[#This Row],[CST_H_E]]+Tabla1[[#This Row],[COS.BASE 2]] -> 52.2 | AF13: =+_xlfn.IFNA(INDEX(RUBRO!$W$2:$AA$732,MATCH(Tabla1[[#This Row],[FECHA ]],RUBRO!$W$2:$W$732,0),5)," ") -> 0 | AG13: =+_xlfn.IFNA(INDEX(RUBRO!$W$2:$AA$732,MATCH(Tabla1[[#This Row],[FECHA ]],RUBRO!$W$2:$W$732,0),2)," ") -> 0 | AH13: =IFERROR(Tabla1[[#This Row],[F]]*Tabla1[[#This Row],[COS.B+E]]," ") -> 0 | AI13: =IFERROR(Tabla1[[#This Row],[COS.B+E]]*Tabla1[[#This Row],[D]]," ") -> 0 | AJ13: =IFERROR(Tabla1[[#This Row],[F]]*#REF!," ") | AK13: =IFERROR(#REF!*Tabla1[[#This Row],[D]]," ") | AO13: =+Tabla1[[#This Row],[COS.B+E]]+Tabla1[[#This Row],[COS.F1]]+Tabla1[[#This Row],[COS.D1]]+Tabla1[[#This Row],[ALIMENTACION]]+Tabla1[[#This Row],[PRESTAMO]]+AN13 -> 52.2 | AP13: =+#REF!+Tabla1[[#This Row],[COS F2]]+Tabla1[[#This Row],[COS D2]]+Tabla1[[#This Row],[ALIMENTACION]]+Tabla1[[#This Row],[PRESTAMO]]+Tabla1[[#This Row],[PASAJES]] -> #REF!
A14: =TEXT(Tabla1[[#This Row],[FECHA ]],"DDDDD") -> viernes | B14: =_xlfn.IFNA(VLOOKUP(Tabla1[[#This Row],[DESTINO]],RUBRO!$Q$1:$R$9996,2,FALSE)," ") -> OBRA | C14: =WEEKNUM(Tabla1[[#This Row],[FECHA ]],2) -> 19 | D14: =TEXT(Tabla1[[#This Row],[FECHA ]],"MMM-YY") -> may-YY | E14: =VLOOKUP(Tabla1[[#This Row],[DNI ]],RUBRO!$F$1:$O$9996,7,FALSE) -> 5ta | F14: =VLOOKUP(Tabla1[[#This Row],[DNI ]],RUBRO!$F$1:$O$88,3,FALSE) -> TECME-03 | G14: =VLOOKUP(Tabla1[[#This Row],[DNI ]],RUBRO!$F$1:$O$9996,5,FALSE) -> TECNICO ELECTRICO MONTAJISTA DE MAQUINARIA EXTRANJERA | H14: =VLOOKUP(Tabla1[[#This Row],[DNI ]],RUBRO!$F$1:$O$9996,6,FALSE) -> CHAQUILA JIMENEZ VICTOR JHEYNER | I14: 44323 | J14: 2 | K14: 47055982 | L14: =VLOOKUP(Tabla1[[#This Row],[DNI ]],RUBRO!$F$2:$O$9996,8,FALSE) -> 73.72 | M14: 0.29166667 | N14: 0.54166667 | O14: 0.58333333 | P14: 0.75 | Q14: =(Tabla1[[#This Row],[SALIDA]]-Tabla1[[#This Row],[FIN ]])+(Tabla1[[#This Row],[INICIO]]-Tabla1[[#This Row],[INGRESO]]) -> 0.41666667 | R14: =IF(J14=1,IF(Q14>$AU$1,$AU$1,Q14),0)+IF(J14=2,IF(Q14>$AU$3,$AU$3,Q14),0)+IF(J14=8,IF(Q14>$AU$5,$AU$5,Q14),0) -> 0.33333333 | S14: =IF(J14=1,IF(Q14>$AU$1,(Q14-R14),0),0)+IF(J14=2,IF(Q14>$AU$3,(Q14-R14),0),0)+IF(J14=8,IF(Q14>$AU$5,(Q14-R14),0),0) -> 0.083333333 | V14: =(Tabla1[[#This Row],[COS.BASE 3]]*0.25+Tabla1[[#This Row],[COS.BASE 3]])*Tabla1[[#This Row],[HORAS 25 % ]] -> 0 | W14: =(Tabla1[[#This Row],[COS.BASE 3]]*0.35+Tabla1[[#This Row],[COS.BASE 3]])*Tabla1[[#This Row],[HORAS 35% ]] -> 0 | X14: =SUM(Tabla1[[#This Row],[C.HORA.35]],Tabla1[[#This Row],[C.HORA.25]]) -> 0 | Z14: =Tabla1[[#This Row],[T.HORAS]]*24 -> 10 | AA14: =Tabla1[[#This Row],[H.NORMALES]]*24 -> 8 | AB14: =Tabla1[[#This Row],[H.EXTRAS]]*24 -> 2 | AC14: =IF(J14=1,(((R14*24)*(L14/9))),0)+IF(J14=2,(((R14*24)*(L14/8))),0)+IF(J14=8,(((R14*24)*(L14/8))),0) -> 73.72 | AD14: =Tabla1[[#This Row],[COS.BASE 2]]/8 -> 9.215 | AE14: =Tabla1[[#This Row],[CST_H_E]]+Tabla1[[#This Row],[COS.BASE 2]] -> 73.72 | AF14: =+_xlfn.IFNA(INDEX(RUBRO!$W$2:$AA$732,MATCH(Tabla1[[#This Row],[FECHA ]],RUBRO!$W$2:$W$732,0),5)," ") -> 0 | AG14: =+_xlfn.IFNA(INDEX(RUBRO!$W$2:$AA$732,MATCH(Tabla1[[#This Row],[FECHA ]],RUBRO!$W$2:$W$732,0),2)," ") -> 0 | AH14: =IFERROR(Tabla1[[#This Row],[F]]*Tabla1[[#This Row],[COS.B+E]]," ") -> 0 | AI14: =IFERROR(Tabla1[[#This Row],[COS.B+E]]*Tabla1[[#This Row],[D]]," ") -> 0 | AJ14: =IFERROR(Tabla1[[#This Row],[F]]*#REF!," ") | AK14: =IFERROR(#REF!*Tabla1[[#This Row],[D]]," ") | AO14: =+Tabla1[[#This Row],[COS.B+E]]+Tabla1[[#This Row],[COS.F1]]+Tabla1[[#This Row],[COS.D1]]+Tabla1[[#This Row],[ALIMENTACION]]+Tabla1[[#This Row],[PRESTAMO]]+AN14 -> 73.72 | AP14: =+#REF!+Tabla1[[#This Row],[COS F2]]+Tabla1[[#This Row],[COS D2]]+Tabla1[[#This Row],[ALIMENTACION]]+Tabla1[[#This Row],[PRESTAMO]]+Tabla1[[#This Row],[PASAJES]] -> #REF!
A15: =TEXT(Tabla1[[#This Row],[FECHA ]],"DDDDD") -> viernes | B15: =_xlfn.IFNA(VLOOKUP(Tabla1[[#This Row],[DESTINO]],RUBRO!$Q$1:$R$9996,2,FALSE)," ") -> OBRA | C15: =WEEKNUM(Tabla1[[#This Row],[FECHA ]],2) -> 19 | D15: =TEXT(Tabla1[[#This Row],[FECHA ]],"MMM-YY") -> may-YY | E15: =VLOOKUP(Tabla1[[#This Row],[DNI ]],RUBRO!$F$1:$O$9996,7,FALSE) -> 5ta | F15: =VLOOKUP(Tabla1[[#This Row],[DNI ]],RUBRO!$F$1:$O$88,3,FALSE) -> #N/A | G15: =VLOOKUP(Tabla1[[#This Row],[DNI ]],RUBRO!$F$1:$O$9996,5,FALSE) -> AYUDANTE DE PRODUCCION | H15: =VLOOKUP(Tabla1[[#This Row],[DNI ]],RUBRO!$F$1:$O$9996,6,FALSE) -> COPIA BALDERA NILSON | I15: 44323 | J15: 2 | K15: 48359730 | L15: =VLOOKUP(Tabla1[[#This Row],[DNI ]],RUBRO!$F$2:$O$9996,8,FALSE) -> 55 | M15: 0.29166667 | N15: 0.54166667 | O15: 0.58333333 | P15: 0.75 | Q15: =(Tabla1[[#This Row],[SALIDA]]-Tabla1[[#This Row],[FIN ]])+(Tabla1[[#This Row],[INICIO]]-Tabla1[[#This Row],[INGRESO]]) -> 0.41666667 | R15: =IF(J15=1,IF(Q15>$AU$1,$AU$1,Q15),0)+IF(J15=2,IF(Q15>$AU$3,$AU$3,Q15),0)+IF(J15=8,IF(Q15>$AU$5,$AU$5,Q15),0) -> 0.33333333 | S15: =IF(J15=1,IF(Q15>$AU$1,(Q15-R15),0),0)+IF(J15=2,IF(Q15>$AU$3,(Q15-R15),0),0)+IF(J15=8,IF(Q15>$AU$5,(Q15-R15),0),0) -> 0.083333333 | V15: =(Tabla1[[#This Row],[COS.BASE 3]]*0.25+Tabla1[[#This Row],[COS.BASE 3]])*Tabla1[[#This Row],[HORAS 25 % ]] -> 0 | W15: =(Tabla1[[#This Row],[COS.BASE 3]]*0.35+Tabla1[[#This Row],[COS.BASE 3]])*Tabla1[[#This Row],[HORAS 35% ]] -> 0 | X15: =SUM(Tabla1[[#This Row],[C.HORA.35]],Tabla1[[#This Row],[C.HORA.25]]) -> 0 | Z15: =Tabla1[[#This Row],[T.HORAS]]*24 -> 10 | AA15: =Tabla1[[#This Row],[H.NORMALES]]*24 -> 8 | AB15: =Tabla1[[#This Row],[H.EXTRAS]]*24 -> 2 | AC15: =IF(J15=1,(((R15*24)*(L15/9))),0)+IF(J15=2,(((R15*24)*(L15/8))),0)+IF(J15=8,(((R15*24)*(L15/8))),0) -> 55 | AD15: =Tabla1[[#This Row],[COS.BASE 2]]/8 -> 6.875 | AE15: =Tabla1[[#This Row],[CST_H_E]]+Tabla1[[#This Row],[COS.BASE 2]] -> 55 | AF15: =+_xlfn.IFNA(INDEX(RUBRO!$W$2:$AA$732,MATCH(Tabla1[[#This Row],[FECHA ]],RUBRO!$W$2:$W$732,0),5)," ") -> 0 | AG15: =+_xlfn.IFNA(INDEX(RUBRO!$W$2:$AA$732,MATCH(Tabla1[[#This Row],[FECHA ]],RUBRO!$W$2:$W$732,0),2)," ") -> 0 | AH15: =IFERROR(Tabla1[[#This Row],[F]]*Tabla1[[#This Row],[COS.B+E]]," ") -> 0 | AI15: =IFERROR(Tabla1[[#This Row],[COS.B+E]]*Tabla1[[#This Row],[D]]," ") -> 0 | AJ15: =IFERROR(Tabla1[[#This Row],[F]]*#REF!," ") | AK15: =IFERROR(#REF!*Tabla1[[#This Row],[D]]," ") | AO15: =+Tabla1[[#This Row],[COS.B+E]]+Tabla1[[#This Row],[COS.F1]]+Tabla1[[#This Row],[COS.D1]]+Tabla1[[#This Row],[ALIMENTACION]]+Tabla1[[#This Row],[PRESTAMO]]+AN15 -> 55 | AP15: =+#REF!+Tabla1[[#This Row],[COS F2]]+Tabla1[[#This Row],[COS D2]]+Tabla1[[#This Row],[ALIMENTACION]]+Tabla1[[#This Row],[PRESTAMO]]+Tabla1[[#This Row],[PASAJES]] -> #REF!
A16: =TEXT(Tabla1[[#This Row],[FECHA ]],"DDDDD") -> viernes | B16: =_xlfn.IFNA(VLOOKUP(Tabla1[[#This Row],[DESTINO]],RUBRO!$Q$1:$R$9996,2,FALSE)," ") -> PLANTA | C16: =WEEKNUM(Tabla1[[#This Row],[FECHA ]],2) -> 19 | D16: =TEXT(Tabla1[[#This Row],[FECHA ]],"MMM-YY") -> may-YY | E16: =VLOOKUP(Tabla1[[#This Row],[DNI ]],RUBRO!$F$1:$O$9996,7,FALSE) -> 5ta | F16: =VLOOKUP(Tabla1[[#This Row],[DNI ]],RUBRO!$F$1:$O$88,3,FALSE) -> OPE-01 | G16: =VLOOKUP(Tabla1[[#This Row],[DNI ]],RUBRO!$F$1:$O$9996,5,FALSE) -> OPERARIO SOLDADOR | H16: =VLOOKUP(Tabla1[[#This Row],[DNI ]],RUBRO!$F$1:$O$9996,6,FALSE) -> CORDOVA OJEDA JHON GIAMPIERRE | I16: 44323 | J16: 1 | K16: 74359947 | L16: =VLOOKUP(Tabla1[[#This Row],[DNI ]],RUBRO!$F$2:$O$9996,8,FALSE) -> 57.62 | M16: 0.29166667 | N16: 0.54166667 | O16: 0.58333333 | P16: 0.79166667 | Q16: =(Tabla1[[#This Row],[SALIDA]]-Tabla1[[#This Row],[FIN ]])+(Tabla1[[#This Row],[INICIO]]-Tabla1[[#This Row],[INGRESO]]) -> 0.45833333 | R16: =IF(J16=1,IF(Q16>$AU$1,$AU$1,Q16),0)+IF(J16=2,IF(Q16>$AU$3,$AU$3,Q16),0)+IF(J16=8,IF(Q16>$AU$5,$AU$5,Q16),0) -> 0.375 | S16: =IF(J16=1,IF(Q16>$AU$1,(Q16-R16),0),0)+IF(J16=2,IF(Q16>$AU$3,(Q16-R16),0),0)+IF(J16=8,IF(Q16>$AU$5,(Q16-R16),0),0) -> 0.083333333 | V16: =(Tabla1[[#This Row],[COS.BASE 3]]*0.25+Tabla1[[#This Row],[COS.BASE 3]])*Tabla1[[#This Row],[HORAS 25 % ]] -> 0 | W16: =(Tabla1[[#This Row],[COS.BASE 3]]*0.35+Tabla1[[#This Row],[COS.BASE 3]])*Tabla1[[#This Row],[HORAS 35% ]] -> 0 | X16: =SUM(Tabla1[[#This Row],[C.HORA.35]],Tabla1[[#This Row],[C.HORA.25]]) -> 0 | Z16: =Tabla1[[#This Row],[T.HORAS]]*24 -> 11 | AA16: =Tabla1[[#This Row],[H.NORMALES]]*24 -> 9 | AB16: =Tabla1[[#This Row],[H.EXTRAS]]*24 -> 2 | AC16: =IF(J16=1,(((R16*24)*(L16/9))),0)+IF(J16=2,(((R16*24)*(L16/8))),0)+IF(J16=8,(((R16*24)*(L16/8))),0) -> 57.62 | AD16: =Tabla1[[#This Row],[COS.BASE 2]]/8 -> 7.2025 | AE16: =Tabla1[[#This Row],[CST_H_E]]+Tabla1[[#This Row],[COS.BASE 2]] -> 57.62 | AF16: =+_xlfn.IFNA(INDEX(RUBRO!$W$2:$AA$732,MATCH(Tabla1[[#This Row],[FECHA ]],RUBRO!$W$2:$W$732,0),5)," ") -> 0 | AG16: =+_xlfn.IFNA(INDEX(RUBRO!$W$2:$AA$732,MATCH(Tabla1[[#This Row],[FECHA ]],RUBRO!$W$2:$W$732,0),2)," ") -> 0 | AH16: =IFERROR(Tabla1[[#This Row],[F]]*Tabla1[[#This Row],[COS.B+E]]," ") -> 0 | AI16: =IFERROR(Tabla1[[#This Row],[COS.B+E]]*Tabla1[[#This Row],[D]]," ") -> 0 | AJ16: =IFERROR(Tabla1[[#This Row],[F]]*#REF!," ") | AK16: =IFERROR(#REF!*Tabla1[[#This Row],[D]]," ") | AO16: =+Tabla1[[#This Row],[COS.B+E]]+Tabla1[[#This Row],[COS.F1]]+Tabla1[[#This Row],[COS.D1]]+Tabla1[[#This Row],[ALIMENTACION]]+Tabla1[[#This Row],[PRESTAMO]]+AN16 -> 57.62 | AP16: =+#REF!+Tabla1[[#This Row],[COS F2]]+Tabla1[[#This Row],[COS D2]]+Tabla1[[#This Row],[ALIMENTACION]]+Tabla1[[#This Row],[PRESTAMO]]+Tabla1[[#This Row],[PASAJES]] -> #REF!
A17: =TEXT(Tabla1[[#This Row],[FECHA ]],"DDDDD") -> viernes | B17: =_xlfn.IFNA(VLOOKUP(Tabla1[[#This Row],[DESTINO]],RUBRO!$Q$1:$R$9996,2,FALSE)," ") -> PLANTA | C17: =WEEKNUM(Tabla1[[#This Row],[FECHA ]],2) -> 19 | D17: =TEXT(Tabla1[[#This Row],[FECHA ]],"MMM-YY") -> may-YY | E17: =VLOOKUP(Tabla1[[#This Row],[DNI ]],RUBRO!$F$1:$O$9996,7,FALSE) -> 5ta | F17: =VLOOKUP(Tabla1[[#This Row],[DNI ]],RUBRO!$F$1:$O$88,3,FALSE) -> TEC-02 | G17: =VLOOKUP(Tabla1[[#This Row],[DNI ]],RUBRO!$F$1:$O$9996,5,FALSE) -> TECNICO MECANICO MONTAJISTA DE MAQUINARIA | H17: =VLOOKUP(Tabla1[[#This Row],[DNI ]],RUBRO!$F$1:$O$9996,6,FALSE) -> CORREA TORRES NOYLER | I17: 44323 | J17: 1 | K17: 47321409 | L17: =VLOOKUP(Tabla1[[#This Row],[DNI ]],RUBRO!$F$2:$O$9996,8,FALSE) -> 65 | M17: 0.29166667 | N17: 0.54166667 | O17: 0.58333333 | P17: 0.70833333 | Q17: =(Tabla1[[#This Row],[SALIDA]]-Tabla1[[#This Row],[FIN ]])+(Tabla1[[#This Row],[INICIO]]-Tabla1[[#This Row],[INGRESO]]) -> 0.375 | R17: =IF(J17=1,IF(Q17>$AU$1,$AU$1,Q17),0)+IF(J17=2,IF(Q17>$AU$3,$AU$3,Q17),0)+IF(J17=8,IF(Q17>$AU$5,$AU$5,Q17),0) -> 0.375 | S17: =IF(J17=1,IF(Q17>$AU$1,(Q17-R17),0),0)+IF(J17=2,IF(Q17>$AU$3,(Q17-R17),0),0)+IF(J17=8,IF(Q17>$AU$5,(Q17-R17),0),0) -> 0 | V17: =(Tabla1[[#This Row],[COS.BASE 3]]*0.25+Tabla1[[#This Row],[COS.BASE 3]])*Tabla1[[#This Row],[HORAS 25 % ]] -> 0 | W17: =(Tabla1[[#This Row],[COS.BASE 3]]*0.35+Tabla1[[#This Row],[COS.BASE 3]])*Tabla1[[#This Row],[HORAS 35% ]] -> 0 | X17: =SUM(Tabla1[[#This Row],[C.HORA.35]],Tabla1[[#This Row],[C.HORA.25]]) -> 0 | Z17: =Tabla1[[#This Row],[T.HORAS]]*24 -> 9 | AA17: =Tabla1[[#This Row],[H.NORMALES]]*24 -> 9 | AB17: =Tabla1[[#This Row],[H.EXTRAS]]*24 -> 0 | AC17: =IF(J17=1,(((R17*24)*(L17/9))),0)+IF(J17=2,(((R17*24)*(L17/8))),0)+IF(J17=8,(((R17*24)*(L17/8))),0) -> 65 | AD17: =Tabla1[[#This Row],[COS.BASE 2]]/8 -> 8.125 | AE17: =Tabla1[[#This Row],[CST_H_E]]+Tabla1[[#This Row],[COS.BASE 2]] -> 65 | AF17: =+_xlfn.IFNA(INDEX(RUBRO!$W$2:$AA$732,MATCH(Tabla1[[#This Row],[FECHA ]],RUBRO!$W$2:$W$732,0),5)," ") -> 0 | AG17: =+_xlfn.IFNA(INDEX(RUBRO!$W$2:$AA$732,MATCH(Tabla1[[#This Row],[FECHA ]],RUBRO!$W$2:$W$732,0),2)," ") -> 0 | AH17: =IFERROR(Tabla1[[#This Row],[F]]*Tabla1[[#This Row],[COS.B+E]]," ") -> 0 | AI17: =IFERROR(Tabla1[[#This Row],[COS.B+E]]*Tabla1[[#This Row],[D]]," ") -> 0 | AJ17: =IFERROR(Tabla1[[#This Row],[F]]*#REF!," ") | AK17: =IFERROR(#REF!*Tabla1[[#This Row],[D]]," ") | AO17: =+Tabla1[[#This Row],[COS.B+E]]+Tabla1[[#This Row],[COS.F1]]+Tabla1[[#This Row],[COS.D1]]+Tabla1[[#This Row],[ALIMENTACION]]+Tabla1[[#This Row],[PRESTAMO]]+AN17 -> 65 | AP17: =+#REF!+Tabla1[[#This Row],[COS F2]]+Tabla1[[#This Row],[COS D2]]+Tabla1[[#This Row],[ALIMENTACION]]+Tabla1[[#This Row],[PRESTAMO]]+Tabla1[[#This Row],[PASAJES]] -> #REF!
A18: =TEXT(Tabla1[[#This Row],[FECHA ]],"DDDDD") -> viernes | B18: =_xlfn.IFNA(VLOOKUP(Tabla1[[#This Row],[DESTINO]],RUBRO!$Q$1:$R$9996,2,FALSE)," ") -> OBRA | C18: =WEEKNUM(Tabla1[[#This Row],[FECHA ]],2) -> 19 | D18: =TEXT(Tabla1[[#This Row],[FECHA ]],"MMM-YY") -> may-YY | E18: =VLOOKUP(Tabla1[[#This Row],[DNI ]],RUBRO!$F$1:$O$9996,7,FALSE) -> 5ta | F18: =VLOOKUP(Tabla1[[#This Row],[DNI ]],RUBRO!$F$1:$O$88,3,FALSE) -> TEC-04 | G18: =VLOOKUP(Tabla1[[#This Row],[DNI ]],RUBRO!$F$1:$O$9996,5,FALSE) -> TECNICO MECANICO MONTAJISTA DE MAQUINARIA EXTRANJERA | H18: =VLOOKUP(Tabla1[[#This Row],[DNI ]],RUBRO!$F$1:$O$9996,6,FALSE) -> CUYA CAYCHO DANIEL LORENZO | I18: 44323 | J18: 2 | K18: 70133802 | L18: =VLOOKUP(Tabla1[[#This Row],[DNI ]],RUBRO!$F$2:$O$9996,8,FALSE) -> 66.92 | M18: 0.29166667 | N18: 0.54166667 | O18: 0.58333333 | P18: 0.75 | Q18: =(Tabla1[[#This Row],[SALIDA]]-Tabla1[[#This Row],[FIN ]])+(Tabla1[[#This Row],[INICIO]]-Tabla1[[#This Row],[INGRESO]]) -> 0.41666667 | R18: =IF(J18=1,IF(Q18>$AU$1,$AU$1,Q18),0)+IF(J18=2,IF(Q18>$AU$3,$AU$3,Q18),0)+IF(J18=8,IF(Q18>$AU$5,$AU$5,Q18),0) -> 0.33333333 | S18: =IF(J18=1,IF(Q18>$AU$1,(Q18-R18),0),0)+IF(J18=2,IF(Q18>$AU$3,(Q18-R18),0),0)+IF(J18=8,IF(Q18>$AU$5,(Q18-R18),0),0) -> 0.083333333 | V18: =(Tabla1[[#This Row],[COS.BASE 3]]*0.25+Tabla1[[#This Row],[COS.BASE 3]])*Tabla1[[#This Row],[HORAS 25 % ]] -> 0 | W18: =(Tabla1[[#This Row],[COS.BASE 3]]*0.35+Tabla1[[#This Row],[COS.BASE 3]])*Tabla1[[#This Row],[HORAS 35% ]] -> 0 | X18: =SUM(Tabla1[[#This Row],[C.HORA.35]],Tabla1[[#This Row],[C.HORA.25]]) -> 0 | Z18: =Tabla1[[#This Row],[T.HORAS]]*24 -> 10 | AA18: =Tabla1[[#This Row],[H.NORMALES]]*24 -> 8 | AB18: =Tabla1[[#This Row],[H.EXTRAS]]*24 -> 2 | AC18: =IF(J18=1,(((R18*24)*(L18/9))),0)+IF(J18=2,(((R18*24)*(L18/8))),0)+IF(J18=8,(((R18*24)*(L18/8))),0) -> 66.92 | AD18: =Tabla1[[#This Row],[COS.BASE 2]]/8 -> 8.365 | AE18: =Tabla1[[#This Row],[CST_H_E]]+Tabla1[[#This Row],[COS.BASE 2]] -> 66.92 | AF18: =+_xlfn.IFNA(INDEX(RUBRO!$W$2:$AA$732,MATCH(Tabla1[[#This Row],[FECHA ]],RUBRO!$W$2:$W$732,0),5)," ") -> 0 | AG18: =+_xlfn.IFNA(INDEX(RUBRO!$W$2:$AA$732,MATCH(Tabla1[[#This Row],[FECHA ]],RUBRO!$W$2:$W$732,0),2)," ") -> 0 | AH18: =IFERROR(Tabla1[[#This Row],[F]]*Tabla1[[#This Row],[COS.B+E]]," ") -> 0 | AI18: =IFERROR(Tabla1[[#This Row],[COS.B+E]]*Tabla1[[#This Row],[D]]," ") -> 0 | AJ18: =IFERROR(Tabla1[[#This Row],[F]]*#REF!," ") | AK18: =IFERROR(#REF!*Tabla1[[#This Row],[D]]," ") | AO18: =+Tabla1[[#This Row],[COS.B+E]]+Tabla1[[#This Row],[COS.F1]]+Tabla1[[#This Row],[COS.D1]]+Tabla1[[#This Row],[ALIMENTACION]]+Tabla1[[#This Row],[PRESTAMO]]+AN18 -> 66.92 | AP18: =+#REF!+Tabla1[[#This Row],[COS F2]]+Tabla1[[#This Row],[COS D2]]+Tabla1[[#This Row],[ALIMENTACION]]+Tabla1[[#This Row],[PRESTAMO]]+Tabla1[[#This Row],[PASAJES]] -> #REF!
A19: =TEXT(Tabla1[[#This Row],[FECHA ]],"DDDDD") -> viernes | B19: =_xlfn.IFNA(VLOOKUP(Tabla1[[#This Row],[DESTINO]],RUBRO!$Q$1:$R$9996,2,FALSE)," ") -> PLANTA | C19: =WEEKNUM(Tabla1[[#This Row],[FECHA ]],2) -> 19 | D19: =TEXT(Tabla1[[#This Row],[FECHA ]],"MMM-YY") -> may-YY | E19: =VLOOKUP(Tabla1[[#This Row],[DNI ]],RUBRO!$F$1:$O$9996,7,FALSE) -> 4ta | F19: =VLOOKUP(Tabla1[[#This Row],[DNI ]],RUBRO!$F$1:$O$88,3,FALSE) -> #N/A | G19: =VLOOKUP(Tabla1[[#This Row],[DNI ]],RUBRO!$F$1:$O$9996,5,FALSE) -> TECNICO SOLDADOR | H19: =VLOOKUP(Tabla1[[#This Row],[DNI ]],RUBRO!$F$1:$O$9996,6,FALSE) -> DAMIAN DAMIAN MIGUEL ANGEL | I19: 44323 | J19: 1 | K19: 75494335 | L19: =VLOOKUP(Tabla1[[#This Row],[DNI ]],RUBRO!$F$2:$O$9996,8,FALSE) -> 90 | M19: 0.29166667 | N19: 0.54166667 | O19: 0.55208333 | P19: 0.67708333 | Q19: =(Tabla1[[#This Row],[SALIDA]]-Tabla1[[#This Row],[FIN ]])+(Tabla1[[#This Row],[INICIO]]-Tabla1[[#This Row],[INGRESO]]) -> 0.375 | R19: =IF(J19=1,IF(Q19>$AU$1,$AU$1,Q19),0)+IF(J19=2,IF(Q19>$AU$3,$AU$3,Q19),0)+IF(J19=8,IF(Q19>$AU$5,$AU$5,Q19),0) -> 0.375 | S19: =IF(J19=1,IF(Q19>$AU$1,(Q19-R19),0),0)+IF(J19=2,IF(Q19>$AU$3,(Q19-R19),0),0)+IF(J19=8,IF(Q19>$AU$5,(Q19-R19),0),0) -> 0 | V19: =(Tabla1[[#This Row],[COS.BASE 3]]*0.25+Tabla1[[#This Row],[COS.BASE 3]])*Tabla1[[#This Row],[HORAS 25 % ]] -> 0 | W19: =(Tabla1[[#This Row],[COS.BASE 3]]*0.35+Tabla1[[#This Row],[COS.BASE 3]])*Tabla1[[#This Row],[HORAS 35% ]] -> 0 | X19: =SUM(Tabla1[[#This Row],[C.HORA.35]],Tabla1[[#This Row],[C.HORA.25]]) -> 0 | Z19: =Tabla1[[#This Row],[T.HORAS]]*24 -> 9 | AA19: =Tabla1[[#This Row],[H.NORMALES]]*24 -> 9 | AB19: =Tabla1[[#This Row],[H.EXTRAS]]*24 -> 0 | AC19: =IF(J19=1,(((R19*24)*(L19/9))),0)+IF(J19=2,(((R19*24)*(L19/8))),0)+IF(J19=8,(((R19*24)*(L19/8))),0) -> 90 | AD19: =Tabla1[[#This Row],[COS.BASE 2]]/8 -> 11.25 | AE19: =Tabla1[[#This Row],[CST_H_E]]+Tabla1[[#This Row],[COS.BASE 2]] -> 90 | AF19: =+_xlfn.IFNA(INDEX(RUBRO!$W$2:$AA$732,MATCH(Tabla1[[#This Row],[FECHA ]],RUBRO!$W$2:$W$732,0),5)," ") -> 0 | AG19: =+_xlfn.IFNA(INDEX(RUBRO!$W$2:$AA$732,MATCH(Tabla1[[#This Row],[FECHA ]],RUBRO!$W$2:$W$732,0),2)," ") -> 0 | AH19: =IFERROR(Tabla1[[#This Row],[F]]*Tabla1[[#This Row],[COS.B+E]]," ") -> 0 | AI19: =IFERROR(Tabla1[[#This Row],[COS.B+E]]*Tabla1[[#This Row],[D]]," ") -> 0 | AJ19: =IFERROR(Tabla1[[#This Row],[F]]*#REF!," ") | AK19: =IFERROR(#REF!*Tabla1[[#This Row],[D]]," ") | AO19: =+Tabla1[[#This Row],[COS.B+E]]+Tabla1[[#This Row],[COS.F1]]+Tabla1[[#This Row],[COS.D1]]+Tabla1[[#This Row],[ALIMENTACION]]+Tabla1[[#This Row],[PRESTAMO]]+AN19 -> 90 | AP19: =+#REF!+Tabla1[[#This Row],[COS F2]]+Tabla1[[#This Row],[COS D2]]+Tabla1[[#This Row],[ALIMENTACION]]+Tabla1[[#This Row],[PRESTAMO]]+Tabla1[[#This Row],[PASAJES]] -> #REF!
A20: =TEXT(Tabla1[[#This Row],[FECHA ]],"DDDDD") -> viernes | B20: =_xlfn.IFNA(VLOOKUP(Tabla1[[#This Row],[DESTINO]],RUBRO!$Q$1:$R$9996,2,FALSE)," ") -> PLANTA | C20: =WEEKNUM(Tabla1[[#This Row],[FECHA ]],2) -> 19 | D20: =TEXT(Tabla1[[#This Row],[FECHA ]],"MMM-YY") -> may-YY | E20: =VLOOKUP(Tabla1[[#This Row],[DNI ]],RUBRO!$F$1:$O$9996,7,FALSE) -> 5ta | F20: =VLOOKUP(Tabla1[[#This Row],[DNI ]],RUBRO!$F$1:$O$88,3,FALSE) -> #N/A | G20: =VLOOKUP(Tabla1[[#This Row],[DNI ]],RUBRO!$F$1:$O$9996,5,FALSE) -> AYUDANTE DE PRODUCCION | H20: =VLOOKUP(Tabla1[[#This Row],[DNI ]],RUBRO!$F$1:$O$9996,6,FALSE) -> DELGADO CORONADO ROBERTO | I20: 44323 | J20: 1 | K20: 76288149 | L20: =VLOOKUP(Tabla1[[#This Row],[DNI ]],RUBRO!$F$2:$O$9996,8,FALSE) -> 44.32 | M20: 0.29166667 | N20: 0.54166667 | O20: 0.58333333 | P20: 0.75 | Q20: =(Tabla1[[#This Row],[SALIDA]]-Tabla1[[#This Row],[FIN ]])+(Tabla1[[#This Row],[INICIO]]-Tabla1[[#This Row],[INGRESO]]) -> 0.41666667 | R20: =IF(J20=1,IF(Q20>$AU$1,$AU$1,Q20),0)+IF(J20=2,IF(Q20>$AU$3,$AU$3,Q20),0)+IF(J20=8,IF(Q20>$AU$5,$AU$5,Q20),0) -> 0.375 | S20: =IF(J20=1,IF(Q20>$AU$1,(Q20-R20),0),0)+IF(J20=2,IF(Q20>$AU$3,(Q20-R20),0),0)+IF(J20=8,IF(Q20>$AU$5,(Q20-R20),0),0) -> 0.041666667 | V20: =(Tabla1[[#This Row],[COS.BASE 3]]*0.25+Tabla1[[#This Row],[COS.BASE 3]])*Tabla1[[#This Row],[HORAS 25 % ]] -> 0 | W20: =(Tabla1[[#This Row],[COS.BASE 3]]*0.35+Tabla1[[#This Row],[COS.BASE 3]])*Tabla1[[#This Row],[HORAS 35% ]] -> 0 | X20: =SUM(Tabla1[[#This Row],[C.HORA.35]],Tabla1[[#This Row],[C.HORA.25]]) -> 0 | Z20: =Tabla1[[#This Row],[T.HORAS]]*24 -> 10 | AA20: =Tabla1[[#This Row],[H.NORMALES]]*24 -> 9 | AB20: =Tabla1[[#This Row],[H.EXTRAS]]*24 -> 1 | AC20: =IF(J20=1,(((R20*24)*(L20/9))),0)+IF(J20=2,(((R20*24)*(L20/8))),0)+IF(J20=8,(((R20*24)*(L20/8))),0) -> 44.32 | AD20: =Tabla1[[#This Row],[COS.BASE 2]]/8 -> 5.54 | AE20: =Tabla1[[#This Row],[CST_H_E]]+Tabla1[[#This Row],[COS.BASE 2]] -> 44.32 | AF20: =+_xlfn.IFNA(INDEX(RUBRO!$W$2:$AA$732,MATCH(Tabla1[[#This Row],[FECHA ]],RUBRO!$W$2:$W$732,0),5)," ") -> 0 | AG20: =+_xlfn.IFNA(INDEX(RUBRO!$W$2:$AA$732,MATCH(Tabla1[[#This Row],[FECHA ]],RUBRO!$W$2:$W$732,0),2)," ") -> 0 | AH20: =IFERROR(Tabla1[[#This Row],[F]]*Tabla1[[#This Row],[COS.B+E]]," ") -> 0 | AI20: =IFERROR(Tabla1[[#This Row],[COS.B+E]]*Tabla1[[#This Row],[D]]," ") -> 0 | AJ20: =IFERROR(Tabla1[[#This Row],[F]]*#REF!," ") | AK20: =IFERROR(#REF!*Tabla1[[#This Row],[D]]," ") | AO20: =+Tabla1[[#This Row],[COS.B+E]]+Tabla1[[#This Row],[COS.F1]]+Tabla1[[#This Row],[COS.D1]]+Tabla1[[#This Row],[ALIMENTACION]]+Tabla1[[#This Row],[PRESTAMO]]+AN20 -> 44.32 | AP20: =+#REF!+Tabla1[[#This Row],[COS F2]]+Tabla1[[#This Row],[COS D2]]+Tabla1[[#This Row],[ALIMENTACION]]+Tabla1[[#This Row],[PRESTAMO]]+Tabla1[[#This Row],[PASAJES]] -> #REF!
